Workbook

Sheet INV
A1: # | B1: CÓDIGO | C1: COD. REF. | D1: PRODUCTO | E1: DESCRIPCIÓN | F1: COSTO EN DIVISAS
A2: 01 | B2: UDAM001 | C2: 700231 | D2: ALAMBRE DE SOLDADURA MIG DE ACERO INOXIDABLE 308 11,3KG X 0,035" (0,9MM) SUA | E2: ALAMBRE DE SOLDADURA MIG DE ACERO INOXIDABLE ER308L 11,3KG X 0,035" (0,9MM)
A3: 02 | B3: UDAM002 | C3: 700232 | D3: ALAMBRE DE SOLDADURA MIG DE ACERO INOXIDABLE ER308L 15KG X 0,035" (0,9MM) SUA | E3: ALAMBRE DE SOLDADURA MIG DE ACERO INOXIDABLE ER308L 15KG X 0,035" (0,9MM) SUA
A4: 03 | B4: UDAM003 | C4: 700233 | D4: ALAMBRE DE SOLDADURA MIG DE ALUMINIO ER5356 - 16LB (7,27 KG) X 0.045" (1.2MM) | E4: ALAMBRE DE SOLDADURA MIG DE ALUMINIO ER5356 - 16LB (7,27 KG) X 0.045" (1.2MM)
A5: 04 | B5: UDAM004 | C5: 700234 | D5: ALAMBRE DE SOLDADURA MIG DE ALUMINIO ER5356 - 1LB (0,45 KG) X 0.035" (0.9MM) | E5: ALAMBRE DE SOLDADURA MIG DE ALUMINIO ER5356 - 1LB (0,45 KG) X 0.035" (0.9MM)
A6: 05 | B6: UDAM005 | C6: 700235 | D6: ALAMBRE MIG E71T-11 CON FUNDENTE INTERNO (FLUXCORED) - MULTIPASO NO REQUIERE GAS - 2 LB | E6: ALAMBRE MIG E71T-11 CON FUNDENTE INTERNO (FLUXCORED) - MULTIPASO NO REQUIERE GAS - 2 LB
A7: 06 | B7: UDAM006 | C7: 700236 | D7: ALAMBRE MIG DE ALUMINIO ER4043 .035" - 0.9 mm SUA 16 LBS - 7,27 KG | E7: ALAMBRE MIG DE ALUMINIO ER4043 .035" - 0.9 mm SUA 16 LBS - 7,27 KG
A8: 07 | B8: UDAM007 | C8: 700237 | D8: CABLE PARA SOLDAR FLEX-A-PRENE CALIBRE 1/0 AWG / BATERÍA, NEGRO, 600 V, FABRICADO EN EE. UU. | E8: CABLE PARA SOLDAR FLEX-A-PRENE CALIBRE 1/0 AWG / BATERÍA, NEGRO, 600 V, FABRICADO EN EE. UU.
A9: 08 | B9: UDAM008 | C9: 700238 | D9: CABLE PARA SOLDAR FLEX-A-PRENE CALIBRE 2/0 AWG / BATERÍA, NEGRO, 600 V, FABRICADO EN EE. UU. | E9: CABLE PARA SOLDAR FLEX-A-PRENE CALIBRE 2/0 AWG / BATERÍA, NEGRO, 600 V, FABRICADO EN EE. UU.
A10: 09 | B10: UDAM009 | C10: 700239 | D10: CABLE PARA SOLDAR FLEX-A-PRENE CALIBRE 4 AWG / BATERÍA, NEGRO, 600 V, FABRICADO EN EE. UU. | E10: CABLE PARA SOLDAR FLEX-A-PRENE CALIBRE 4 AWG / BATERÍA, NEGRO, 600 V, FABRICADO EN EE. UU.
A11: 10 | B11: UDAM010 | C11: 700240 | D11: CABLE PARA SOLDAR FLEX-A-PRENE CALIBRE 4/0 AWG / BATERÍA, NEGRO, 600 V, FABRICADO EN EE. UU. | E11: CABLE PARA SOLDAR FLEX-A-PRENE CALIBRE 4/0 AWG / BATERÍA, NEGRO, 600 V, FABRICADO EN EE. UU.
A12: 11 | B12: UDAM011 | C12: 700241 | D12: ENVASE - HUMIFICADOR PARA OXIGENO MEDICINAL | E12: ENVASE - HUMIFICADOR PARA OXIGENO MEDICINAL
A13: 12 | B13: UDAM012 | C13: 700242 | D13: EQUIPO SUA DE OXICORTE WYVERN H - TRABAJO MEDIANO / PESADO, TIPO HARRIS. MALETA PLÁSTICA | E13: EQUIPO SUA DE OXICORTE WYVERN H - TRABAJO MEDIANO / PESADO, TIPO HARRIS. MALETA PLÁSTICA
A14: 13 | B14: UDAM013 | C14: 700243 | D14: FLUJÓMETRO - REGULADOR DE OXÍGENO MEDICINAL - PARED. MODELO FM1978-15L-CH | E14: FLUJÓMETRO - REGULADOR DE OXÍGENO MEDICINAL - PARED. MODELO FM1978-15L-CH | F14: 110.58
A15: 14 | B15: UDAM014 | C15: 700244 | D15: FLUJÓMETRO - REGULADOR DE OXÍGENO MEDICINAL CONEXIÓN CGA540 1,8" - JAPAN | E15: FLUJÓMETRO - REGULADOR DE OXÍGENO MEDICINAL CONEXIÓN CGA540 1,8" - JAPAN | F15: 90
A16: 15 | B16: UDAM015 | C16: 700245 | D16: FLUJÓMETRO - REGULADOR PARA CO2 | E16: FLUJÓMETRO - REGULADOR PARA CO2 | F16: 40
A17: 16 | B17: UDAM016 | C17: 700246 | D17: FLUJÓMETRO - REGULADOR DE ARGON DE 2" PARA TIG Y MIG CGA-580 MODELO MD SÜA | E17: FLUJÓMETRO - REGULADOR DE ARGON DE 2" PARA TIG Y MIG CGA-580 MODELO MD SÜA | F17: 60
A18: 17 | B18: UDAM017 | C18: 700247 | D18: MANGUERA DE GAS REFRIGERANTE - 60" (150CM) DE 800 A 4000 PSI - CONECTORES DE 1/4" FLARE (HEMBRA) | E18: MANGUERA DE GAS REFRIGERANTE - 60" (150CM) DE 800 A 4000 PSI - CONECTORES DE 1/4" FLARE (HEMBRA) | F18: 10
A19: 18 | B19: UDAM018 | C19: 700248 | D19: MANGUERA SUA DOBLE PARA OXICORTE DE 100 PIES - 30 M CON CONEXIONES ACOPLADAS | E19: MANGUERA SUA DOBLE PARA OXICORTE DE 100 PIES - 30 M CON CONEXIONES ACOPLADAS | F19: 160
A20: 19 | B20: UDAM019 | C20: 700249 | D20: MANGUERA SUA DOBLE PARA OXICORTE DE 15 PIES - 7,6 M CON CONEXIONES ACOPLADAS | E20: MANGUERA SUA DOBLE PARA OXICORTE DE 15 PIES - 7,6 M CON CONEXIONES ACOPLADAS | F20: 55
A21: 20 | B21: UDAM020 | C21: 700250 | D21: MANGUERA SUA DOBLE PARA OXICORTE DE 50 PIES - 15 M CON CONEXIONES ACOPLADAS | E21: MANGUERA SUA DOBLE PARA OXICORTE DE 50 PIES - 15 M CON CONEXIONES ACOPLADAS | F21: 85
A22: 21 | B22: UDAM021 | C22: 700251 | D22: MANGUERA SUA DOBLE PARA OXICORTE POR METRO (SIN CONEXIONES) | E22: MANGUERA SUA DOBLE PARA OXICORTE POR METRO (SIN CONEXIONES) | F22: 5
A23: 22 | B23: UDAM022 | C23: 700252
A24: 23 | B24: UDAM023 | C24: 700253 | D24: REGULADOR - MANÓMETRO DE GAS INERTE, ARGÓN, CO2, NITRÓGENO, HELIO, HIDRÓGENO DE ALTO FLUJO PARA TRABAJO PESADO DE 2,5" | E24: REGULADOR - MANÓMETRO DE GAS INERTE, ARGÓN, CO2, NITRÓGENO, HELIO, HIDRÓGENO DE ALTO FLUJO PARA TRABAJO PESADO DE 2,5" | F24: 180
A25: 24 | B25: UDAM024 | C25: 700254 | D25: REGULADOR - MANÓMETRO DE O2 - OXÍGENO MEDIANO/PESADO DE 2,5" TIPO VICTOR MODELO V350 | E25: REGULADOR - MANÓMETRO DE O2 - OXÍGENO MEDIANO/PESADO DE 2,5" TIPO VICTOR MODELO V350 | F25: 70
A26: 25 | B26: UDAM025 | C26: 700255 | D26: REGULADOR - MANÓMETRO DE OXÍGENO - GAS 2,5" (25HX-580) SUA | E26: REGULADOR - MANÓMETRO DE OXÍGENO - GAS 2,5" (25HX-580) SUA | F26: 70
A27: 26 | B27: UDAM026 | C27: 700256 | D27: REGULADOR - MANÓMETRO DE OXIGENO MEDICINAL TIPO WESTERN - SALIDA DISS - CGA-540 / 2" | E27: REGULADOR - MANÓMETRO DE OXIGENO MEDICINAL TIPO WESTERN - SALIDA DISS - CGA-540 / 2" | F27: 110.25
A28: 27 | B28: UDAM027 | C28: 700257 | D28: REGULADOR DE ACETILENO 2" CGA-200 CONEXIÓN POSTERIOR MODELO LDP. SUA | E28: REGULADOR DE ACETILENO 2" CGA-200 CONEXIÓN POSTERIOR MODELO LDP. SUA | F28: 50
A29: 28 | B29: UDAM028 | C29: 700258 | D29: REGULADOR DE CO2 PARA SISTEMAS DISPENSADORES DE BEBIDAS CARBONATADAS - SUA | E29: REGULADOR DE CO2 PARA SISTEMAS DISPENSADORES DE BEBIDAS CARBONATADAS - SUA | F29: 110
A30: 29 | B30: UDAM029 | C30: 700259 | D30: REGULADOR DE GAS INERTE 2" / NITRÓGENO, ARGÓN, HELIO. CGA-580 9/16 | E30: REGULADOR DE GAS INERTE 2" / NITRÓGENO, ARGÓN, HELIO. CGA-580 9/16 | F30: 70
A31: 30 | B31: UDAM030 | C31: 700260 | D31: REGULADOR DE GAS NITRÓGENO 2" DE 0 A 4000 PSI - PURGA DE HVAC - CARGA DE PRESIÓN - CONECTOR ABROCADO. SUA | E31: REGULADOR DE GAS NITRÓGENO 2" DE 0 A 4000 PSI - PURGA DE HVAC - CARGA DE PRESIÓN - CONECTOR ABROCADO. SUA | F31: 80
A32: 31 | B32: UDAM031 | C32: 700261 | D32: REGULADOR DE OXIGENO MEDICINAL TIPO CLICK 0-15 LPM - SALIDA DISS CON ADAPTADOR DE MANGUERA - CGA-540 | E32: REGULADOR DE OXIGENO MEDICINAL TIPO CLICK 0-15 LPM - SALIDA DISS CON ADAPTADOR DE MANGUERA - CGA-540 | F32: 50
A33: 32 | B33: UDAM032 | C33: 700262 | D33: REGULADOR DE PROPANO 1,8" CGA-510 CONEXIÓN POSTERIOR MODELO LDP. SUA | E33: REGULADOR DE PROPANO 1,8" CGA-510 CONEXIÓN POSTERIOR MODELO LDP. SUA | F33: 50
A34: 33 | B34: UDAM033 | C34: 700263 | D34: REGULADOR DE PROPANO 2,5" 25HX - 510A SUA | E34: REGULADOR DE PROPANO 2,5" 25HX - 510A SUA | F34: 70
A35: 34 | B35: UDAM034 | C35: 700264 | D35: REGULADOR MANÓMETRO DE OXIGENO 1,8" CGA-540 CONEXIÓN POSTERIOR MODELO LDP SUA | E35: REGULADOR MANÓMETRO DE OXIGENO 1,8" CGA-540 CONEXIÓN POSTERIOR MODELO LDP SUA | F35: 50
... A43: 42 | B43: UDAM042 | C43: 700272 | D43: REGULADOR DE LINEA PARA GASES | E43: REGULADOR DE LINEA PARA GASES | F43: 90
A44: 43 | B44: UDAM043 | C44: 700273
A45: 44 | B45: UDAM044 | C45: 700274
A46: 45 | B46: UDAM045 | C46: 700275
A47: 46 | B47: UDAM046 | C47: 700276
...

Sheet NOTA $
A1: NOTA DE ENTREGA
B5: SUMINISTROS Y ACCESORIOS CARABOBO
B6: AV. ANDRÉS BELLO C/C LÓPEZ, LOCAL NRO, 87-66 SECTOR LA CANDELA
B7: RIF: J075102593
B8: TELÉFONO: 0212-8870026
B10: CLIENTE: | G10: FECHA: | H10: =NOW() -> 46280.588
B12: C.I. / RIF: | G12: N° DOC: | H12: =51437+H10+F34 -> 97717.588
B14: TELÉFONO: | G14: VENDEDOR: | H14: V-09036
B16: DIRECCION: | G16: TIPO DE PAGO: | H16: EFECTIVO ($)
G17: DESCUENTO: | H17: NO
B19: CÓDIGO | C19: CÓD. UNIX | D19: DESCRIPCIÓN | F19: CANTIDAD | G19: COSTO $ | H19: A PAGAR
C21: =IF(B21="","",IF(B21=INV!B2,INV!C2,IF(B21=INV!B3,INV!C3,IF(B21=INV!B4,INV!C4,IF(B21=INV!B5,INV!C5,IF(B21=INV!B6,INV!C6,IF(B21=INV!B7,INV!C7,IF(B21=INV!B8,INV!C8,IF(B21=INV!B9,INV!C9,IF(B21=INV!B10,INV!C10,IF(B21=INV!B11,INV!C11,IF(B21=INV!B12,INV!C12,IF(B21=INV!B13,INV!C13,IF(B21=INV!B14,INV!C14,IF(B21=INV!B15,INV!C15,IF(B21=INV!B16,INV!C16,IF(B21=INV!B17,INV!C17,IF(B21=INV!B18,INV!C18,IF(B21=INV!B19,INV!C19,IF(B21=INV!B20,INV!C20,IF(B21=INV!B21,INV!C21,IF(B21=INV!B22,INV!C22,IF(B21=INV!B23,INV!C23,IF(B21=INV!B24,INV!C24,IF(B21=INV!B25,INV!C25,IF(B21=INV!B26,INV!C26,IF(B21=INV!B27,INV!C27,IF(B21=INV!B28,INV!C28,IF(B21=INV!B29,INV!C29,IF(B21=INV!B30,INV!C30,IF(B21=INV!B31,INV!C31,IF(B21=INV!B32,INV!C322,IF(B21=INV!B33,INV!C33,IF(B21=INV!B34,INV!C34,IF(B21=INV!B35,INV!C35,IF(B21=INV!B36,INV!C36,IF(B21=INV!B37,INV!C37,IF(B21=INV!B38,INV!C38,IF(B21=INV!B39,INV!C39,IF(B21=INV!B40,INV!C40,IF(B21=INV!B41,INV!C41,IF(B21=INV!B42,INV!C42,IF(B21=INV!B43,INV!C43,IF(B21=INV!B44,INV!C44,IF(B21=INV!B45,INV!C45,IF(B21=INV!B46,INV!C46,IF(B21=INV!B47,INV!C47,IF(B21=INV!B48,INV!C48,IF(B21=INV!B49,INV!C49,IF(B21=INV!B50,INV!C50,IF(B21=INV!B51,INV!C51))))))))))))))))))))))))))))))))))))))))))))))))))) | D21: =IF(C21="","",IF(C21=INV!C2,INV!D2,IF(C21=INV!C3,INV!D3,IF(C21=INV!C4,INV!D4,IF(C21=INV!C5,INV!D5,IF(C21=INV!C6,INV!D6,IF(C21=INV!C7,INV!D7,IF(C21=INV!C8,INV!D8,IF(C21=INV!C9,INV!D9,IF(C21=INV!C10,INV!D10,IF(C21=INV!C11,INV!D11,IF(C21=INV!C12,INV!D12,IF(C21=INV!C13,INV!D13,IF(C21=INV!C14,INV!D14,IF(C21=INV!C15,INV!D15,IF(C21=INV!C16,INV!D16,IF(C21=INV!C17,INV!D17,IF(C21=INV!C18,INV!D18,IF(C21=INV!C19,INV!D19,IF(C21=INV!C20,INV!D20,IF(C21=INV!C21,INV!D21,IF(C21=INV!C22,INV!D22,IF(C21=INV!C23,INV!D23,IF(C21=INV!C24,INV!D24,IF(C21=INV!C25,INV!D25,IF(C21=INV!C26,INV!D26,IF(C21=INV!C27,INV!D27,IF(C21=INV!C28,INV!D28,IF(C21=INV!C29,INV!D29,IF(C21=INV!C30,INV!D30,IF(C21=INV!C31,INV!D31,IF(C21=INV!C32,INV!D322,IF(C21=INV!C33,INV!D33,IF(C21=INV!C34,INV!D34,IF(C21=INV!C35,INV!D35,IF(C21=INV!C36,INV!D36,IF(C21=INV!C37,INV!D37,IF(C21=INV!C38,INV!D38,IF(C21=INV!C39,INV!D39,IF(C21=INV!C40,INV!D40,IF(C21=INV!C41,INV!D41,IF(C21=INV!C42,INV!D42,IF(C21=INV!C43,INV!D43,IF(C21=INV!C44,INV!D44,IF(C21=INV!C45,INV!D45,IF(C21=INV!C46,INV!D46,IF(C21=INV!C47,INV!D47,IF(C21=INV!C48,INV!D48,IF(C21=INV!C49,INV!D49,IF(C21=INV!C50,INV!D50,IF(C21=INV!C51,INV!D51))))))))))))))))))))))))))))))))))))))))))))))))))) | G21: =IF(B21="","",IF(B21=INV!B2,INV!F2,IF(B21=INV!B3,INV!F3,IF(B21=INV!B4,INV!F4,IF(B21=INV!B5,INV!F5,IF(B21=INV!B6,INV!F6,IF(B21=INV!B7,INV!F7,IF(B21=INV!B8,INV!F8,IF(B21=INV!B9,INV!F9,IF(B21=INV!B10,INV!F10,IF(B21=INV!B11,INV!F11,IF(B21=INV!B12,INV!F12,IF(B21=INV!B13,INV!F13,IF(B21=INV!B14,INV!F14,IF(B21=INV!B15,INV!F15,IF(B21=INV!B16,INV!F16,IF(B21=INV!B17,INV!F17,IF(B21=INV!B18,INV!F18,IF(B21=INV!B19,INV!F19,IF(B21=INV!B20,INV!F20,IF(B21=INV!B21,INV!F21,IF(B21=INV!B22,INV!F22,IF(B21=INV!B23,INV!F23,IF(B21=INV!B24,INV!F24,IF(B21=INV!B25,INV!F25,IF(B21=INV!B26,INV!F26,IF(B21=INV!B27,INV!F27,IF(B21=INV!B28,INV!F28,IF(B21=INV!B29,INV!F29,IF(B21=INV!B30,INV!F30,IF(B21=INV!B31,INV!F31,IF(B21=INV!B32,INV!F32,IF(B21=INV!B33,INV!F33,IF(B21=INV!B34,INV!F34,IF(B21=INV!B35,INV!F35,IF(B21=INV!B36,INV!F36,IF(B21=INV!B37,INV!F37,IF(B21=INV!B38,INV!F38,IF(B21=INV!B39,INV!F39,IF(B21=INV!B40,INV!F40,IF(B21=INV!B41,INV!F41,IF(B21=INV!B42,INV!F42,IF(B21=INV!B43,INV!F43,IF(B21=INV!B44,INV!F44,IF(B21=INV!B45,INV!F45,IF(B21=INV!B46,INV!F46,IF(B21=INV!B47,INV!F47,IF(B21=INV!B48,INV!F48,IF(B21=INV!B49,INV!F49,IF(B21=INV!B51,INV!F51)))))))))))))))))))))))))))))))))))))))))))))))))) | H21: =IF(F21="","",G21*F21)
C22: =IF(B22="","",IF(B22=INV!B2,INV!C2,IF(B22=INV!B3,INV!C3,IF(B22=INV!B4,INV!C4,IF(B22=INV!B5,INV!C5,IF(B22=INV!B6,INV!C6,IF(B22=INV!B7,INV!C7,IF(B22=INV!B8,INV!C8,IF(B22=INV!B9,INV!C9,IF(B22=INV!B10,INV!C10,IF(B22=INV!B11,INV!C11,IF(B22=INV!B12,INV!C12,IF(B22=INV!B13,INV!C13,IF(B22=INV!B14,INV!C14,IF(B22=INV!B15,INV!C15,IF(B22=INV!B16,INV!C16,IF(B22=INV!B17,INV!C17,IF(B22=INV!B18,INV!C18,IF(B22=INV!B19,INV!C19,IF(B22=INV!B20,INV!C20,IF(B22=INV!B21,INV!C21,IF(B22=INV!B22,INV!C22,IF(B22=INV!B23,INV!C23,IF(B22=INV!B24,INV!C24,IF(B22=INV!B25,INV!C25,IF(B22=INV!B26,INV!C26,IF(B22=INV!B27,INV!C27,IF(B22=INV!B28,INV!C28,IF(B22=INV!B29,INV!C29,IF(B22=INV!B30,INV!C30,IF(B22=INV!B31,INV!C31,IF(B22=INV!B32,INV!C32,IF(B22=INV!B33,INV!C323,IF(B22=INV!B34,INV!C34,IF(B22=INV!B35,INV!C35,IF(B22=INV!B36,INV!C36,IF(B22=INV!B37,INV!C37,IF(B22=INV!B38,INV!C38,IF(B22=INV!B39,INV!C39,IF(B22=INV!B40,INV!C40,IF(B22=INV!B41,INV!C41,IF(B22=INV!B42,INV!C42,IF(B22=INV!B43,INV!C43,IF(B22=INV!B44,INV!C44,IF(B22=INV!B45,INV!C45,IF(B22=INV!B46,INV!C46,IF(B22=INV!B47,INV!C47,IF(B22=INV!B48,INV!C48,IF(B22=INV!B49,INV!C49,IF(B22=INV!B50,INV!C50,IF(B22=INV!B51,INV!C51,IF(B22=INV!B52,INV!C52)))))))))))))))))))))))))))))))))))))))))))))))))))) | D22: =IF(C22="","",IF(C22=INV!C2,INV!D2,IF(C22=INV!C3,INV!D3,IF(C22=INV!C4,INV!D4,IF(C22=INV!C5,INV!D5,IF(C22=INV!C6,INV!D6,IF(C22=INV!C7,INV!D7,IF(C22=INV!C8,INV!D8,IF(C22=INV!C9,INV!D9,IF(C22=INV!C10,INV!D10,IF(C22=INV!C11,INV!D11,IF(C22=INV!C12,INV!D12,IF(C22=INV!C13,INV!D13,IF(C22=INV!C14,INV!D14,IF(C22=INV!C15,INV!D15,IF(C22=INV!C16,INV!D16,IF(C22=INV!C17,INV!D17,IF(C22=INV!C18,INV!D18,IF(C22=INV!C19,INV!D19,IF(C22=INV!C20,INV!D20,IF(C22=INV!C21,INV!D21,IF(C22=INV!C22,INV!D22,IF(C22=INV!C23,INV!D23,IF(C22=INV!C24,INV!D24,IF(C22=INV!C25,INV!D25,IF(C22=INV!C26,INV!D26,IF(C22=INV!C27,INV!D27,IF(C22=INV!C28,INV!D28,IF(C22=INV!C29,INV!D29,IF(C22=INV!C30,INV!D30,IF(C22=INV!C31,INV!D31,IF(C22=INV!C32,INV!D32,IF(C22=INV!C33,INV!D323,IF(C22=INV!C34,INV!D34,IF(C22=INV!C35,INV!D35,IF(C22=INV!C36,INV!D36,IF(C22=INV!C37,INV!D37,IF(C22=INV!C38,INV!D38,IF(C22=INV!C39,INV!D39,IF(C22=INV!C40,INV!D40,IF(C22=INV!C41,INV!D41,IF(C22=INV!C42,INV!D42,IF(C22=INV!C43,INV!D43,IF(C22=INV!C44,INV!D44,IF(C22=INV!C45,INV!D45,IF(C22=INV!C46,INV!D46,IF(C22=INV!C47,INV!D47,IF(C22=INV!C48,INV!D48,IF(C22=INV!C49,INV!D49,IF(C22=INV!C50,INV!D50,IF(C22=INV!C51,INV!D51,IF(C22=INV!C52,INV!D52)))))))))))))))))))))))))))))))))))))))))))))))))))) | G22: =IF(B22="","",IF(B22=INV!B2,INV!F2,IF(B22=INV!B3,INV!F3,IF(B22=INV!B4,INV!F4,IF(B22=INV!B5,INV!F5,IF(B22=INV!B6,INV!F6,IF(B22=INV!B7,INV!F7,IF(B22=INV!B8,INV!F8,IF(B22=INV!B9,INV!F9,IF(B22=INV!B10,INV!F10,IF(B22=INV!B11,INV!F11,IF(B22=INV!B12,INV!F12,IF(B22=INV!B13,INV!F13,IF(B22=INV!B14,INV!F14,IF(B22=INV!B15,INV!F15,IF(B22=INV!B16,INV!F16,IF(B22=INV!B17,INV!F17,IF(B22=INV!B18,INV!F18,IF(B22=INV!B19,INV!F19,IF(B22=INV!B20,INV!F20,IF(B22=INV!B21,INV!F21,IF(B22=INV!B22,INV!F22,IF(B22=INV!B23,INV!F23,IF(B22=INV!B24,INV!F24,IF(B22=INV!B25,INV!F25,IF(B22=INV!B26,INV!F26,IF(B22=INV!B27,INV!F27,IF(B22=INV!B28,INV!F28,IF(B22=INV!B29,INV!F29,IF(B22=INV!B30,INV!F30,IF(B22=INV!B31,INV!F31,IF(B22=INV!B32,INV!F32,IF(B22=INV!B33,INV!F33,IF(B22=INV!B34,INV!F34,IF(B22=INV!B35,INV!F35,IF(B22=INV!B36,INV!F36,IF(B22=INV!B37,INV!F37,IF(B22=INV!B38,INV!F38,IF(B22=INV!B39,INV!F39,IF(B22=INV!B40,INV!F40,IF(B22=INV!B41,INV!F41,IF(B22=INV!B42,INV!F42,IF(B22=INV!B43,INV!F43,IF(B22=INV!B44,INV!F44,IF(B22=INV!B45,INV!F45,IF(B22=INV!B46,INV!F46,IF(B22=INV!B47,INV!F47,IF(B22=INV!B48,INV!F48,IF(B22=INV!B49,INV!F49,IF(B22=INV!B50,INV!F50,IF(B22=INV!B51,INV!F51))))))))))))))))))))))))))))))))))))))))))))))))))) | H22: =IF(F22="","",G22*F22)
C23: =IF(B23="","",IF(B23=INV!B2,INV!C2,IF(B23=INV!B3,INV!C3,IF(B23=INV!B4,INV!C4,IF(B23=INV!B5,INV!C5,IF(B23=INV!B6,INV!C6,IF(B23=INV!B7,INV!C7,IF(B23=INV!B8,INV!C8,IF(B23=INV!B9,INV!C9,IF(B23=INV!B10,INV!C10,IF(B23=INV!B11,INV!C11,IF(B23=INV!B12,INV!C12,IF(B23=INV!B13,INV!C13,IF(B23=INV!B14,INV!C14,IF(B23=INV!B15,INV!C15,IF(B23=INV!B16,INV!C16,IF(B23=INV!B17,INV!C17,IF(B23=INV!B18,INV!C18,IF(B23=INV!B19,INV!C19,IF(B23=INV!B20,INV!C20,IF(B23=INV!B21,INV!C21,IF(B23=INV!B22,INV!C22,IF(B23=INV!B23,INV!C23,IF(B23=INV!B24,INV!C24,IF(B23=INV!B25,INV!C25,IF(B23=INV!B26,INV!C26,IF(B23=INV!B27,INV!C27,IF(B23=INV!B28,INV!C28,IF(B23=INV!B29,INV!C29,IF(B23=INV!B30,INV!C30,IF(B23=INV!B31,INV!C31,IF(B23=INV!B32,INV!C32,IF(B23=INV!B33,INV!C33,IF(B23=INV!B34,INV!C324,IF(B23=INV!B35,INV!C35,IF(B23=INV!B36,INV!C36,IF(B23=INV!B37,INV!C37,IF(B23=INV!B38,INV!C38,IF(B23=INV!B39,INV!C39,IF(B23=INV!B40,INV!C40,IF(B23=INV!B41,INV!C41,IF(B23=INV!B42,INV!C42,IF(B23=INV!B43,INV!C43,IF(B23=INV!B44,INV!C44,IF(B23=INV!B45,INV!C45,IF(B23=INV!B46,INV!C46,IF(B23=INV!B47,INV!C47,IF(B23=INV!B48,INV!C48,IF(B23=INV!B49,INV!C49,IF(B23=INV!B50,INV!C50,IF(B23=INV!B51,INV!C51,IF(B23=INV!B52,INV!C52,IF(B23=INV!B53,INV!C53))))))))))))))))))))))))))))))))))))))))))))))))))))) | D23: =IF(C23="","",IF(C23=INV!C2,INV!D2,IF(C23=INV!C3,INV!D3,IF(C23=INV!C4,INV!D4,IF(C23=INV!C5,INV!D5,IF(C23=INV!C6,INV!D6,IF(C23=INV!C7,INV!D7,IF(C23=INV!C8,INV!D8,IF(C23=INV!C9,INV!D9,IF(C23=INV!C10,INV!D10,IF(C23=INV!C11,INV!D11,IF(C23=INV!C12,INV!D12,IF(C23=INV!C13,INV!D13,IF(C23=INV!C14,INV!D14,IF(C23=INV!C15,INV!D15,IF(C23=INV!C16,INV!D16,IF(C23=INV!C17,INV!D17,IF(C23=INV!C18,INV!D18,IF(C23=INV!C19,INV!D19,IF(C23=INV!C20,INV!D20,IF(C23=INV!C21,INV!D21,IF(C23=INV!C22,INV!D22,IF(C23=INV!C23,INV!D23,IF(C23=INV!C24,INV!D24,IF(C23=INV!C25,INV!D25,IF(C23=INV!C26,INV!D26,IF(C23=INV!C27,INV!D27,IF(C23=INV!C28,INV!D28,IF(C23=INV!C29,INV!D29,IF(C23=INV!C30,INV!D30,IF(C23=INV!C31,INV!D31,IF(C23=INV!C32,INV!D32,IF(C23=INV!C33,INV!D33,IF(C23=INV!C34,INV!D324,IF(C23=INV!C35,INV!D35,IF(C23=INV!C36,INV!D36,IF(C23=INV!C37,INV!D37,IF(C23=INV!C38,INV!D38,IF(C23=INV!C39,INV!D39,IF(C23=INV!C40,INV!D40,IF(C23=INV!C41,INV!D41,IF(C23=INV!C42,INV!D42,IF(C23=INV!C43,INV!D43,IF(C23=INV!C44,INV!D44,IF(C23=INV!C45,INV!D45,IF(C23=INV!C46,INV!D46,IF(C23=INV!C47,INV!D47,IF(C23=INV!C48,INV!D48,IF(C23=INV!C49,INV!D49,IF(C23=INV!C50,INV!D50,IF(C23=INV!C51,INV!D51,IF(C23=INV!C52,INV!D52,IF(C23=INV!C53,INV!D53))))))))))))))))))))))))))))))))))))))))))))))))))))) | G23: =IF(B23="","",IF(B23=INV!B2,INV!F2,IF(B23=INV!B3,INV!F3,IF(B23=INV!B4,INV!F4,IF(B23=INV!B5,INV!F5,IF(B23=INV!B6,INV!F6,IF(B23=INV!B7,INV!F7,IF(B23=INV!B8,INV!F8,IF(B23=INV!B9,INV!F9,IF(B23=INV!B10,INV!F10,IF(B23=INV!B11,INV!F11,IF(B23=INV!B12,INV!F12,IF(B23=INV!B13,INV!F13,IF(B23=INV!B14,INV!F14,IF(B23=INV!B15,INV!F15,IF(B23=INV!B16,INV!F16,IF(B23=INV!B17,INV!F17,IF(B23=INV!B18,INV!F18,IF(B23=INV!B19,INV!F19,IF(B23=INV!B20,INV!F20,IF(B23=INV!B21,INV!F21,IF(B23=INV!B22,INV!F22,IF(B23=INV!B23,INV!F23,IF(B23=INV!B24,INV!F24,IF(B23=INV!B25,INV!F25,IF(B23=INV!B26,INV!F26,IF(B23=INV!B27,INV!F27,IF(B23=INV!B28,INV!F28,IF(B23=INV!B29,INV!F29,IF(B23=INV!B30,INV!F30,IF(B23=INV!B31,INV!F31,IF(B23=INV!B32,INV!F32,IF(B23=INV!B33,INV!F33,IF(B23=INV!B34,INV!F34,IF(B23=INV!B35,INV!F35,IF(B23=INV!B36,INV!F36,IF(B23=INV!B37,INV!F37,IF(B23=INV!B38,INV!F38,IF(B23=INV!B39,INV!F39,IF(B23=INV!B40,INV!F40,IF(B23=INV!B41,INV!F41,IF(B23=INV!B42,INV!F42,IF(B23=INV!B43,INV!F43,IF(B23=INV!B44,INV!F44,IF(B23=INV!B45,INV!F45,IF(B23=INV!B46,INV!F46,IF(B23=INV!B47,INV!F47,IF(B23=INV!B48,INV!F48,IF(B23=INV!B49,INV!F49,IF(B23=INV!B50,INV!F50,IF(B23=INV!B51,INV!F51,IF(B23=INV!B53,INV!F53)))))))))))))))))))))))))))))))))))))))))))))))))))) | H23: =IF(F23="","",G23*F23)
C24: =IF(B24="","",IF(B24=INV!B2,INV!C2,IF(B24=INV!B3,INV!C3,IF(B24=INV!B4,INV!C4,IF(B24=INV!B5,INV!C5,IF(B24=INV!B6,INV!C6,IF(B24=INV!B7,INV!C7,IF(B24=INV!B8,INV!C8,IF(B24=INV!B9,INV!C9,IF(B24=INV!B10,INV!C10,IF(B24=INV!B11,INV!C11,IF(B24=INV!B12,INV!C12,IF(B24=INV!B13,INV!C13,IF(B24=INV!B14,INV!C14,IF(B24=INV!B15,INV!C15,IF(B24=INV!B16,INV!C16,IF(B24=INV!B17,INV!C17,IF(B24=INV!B18,INV!C18,IF(B24=INV!B19,INV!C19,IF(B24=INV!B20,INV!C20,IF(B24=INV!B21,INV!C21,IF(B24=INV!B22,INV!C22,IF(B24=INV!B23,INV!C23,IF(B24=INV!B24,INV!C24,IF(B24=INV!B25,INV!C25,IF(B24=INV!B26,INV!C26,IF(B24=INV!B27,INV!C27,IF(B24=INV!B28,INV!C28,IF(B24=INV!B29,INV!C29,IF(B24=INV!B30,INV!C30,IF(B24=INV!B31,INV!C31,IF(B24=INV!B32,INV!C32,IF(B24=INV!B33,INV!C33,IF(B24=INV!B34,INV!C34,IF(B24=INV!B35,INV!C325,IF(B24=INV!B36,INV!C36,IF(B24=INV!B37,INV!C37,IF(B24=INV!B38,INV!C38,IF(B24=INV!B39,INV!C39,IF(B24=INV!B40,INV!C40,IF(B24=INV!B41,INV!C41,IF(B24=INV!B42,INV!C42,IF(B24=INV!B43,INV!C43,IF(B24=INV!B44,INV!C44,IF(B24=INV!B45,INV!C45,IF(B24=INV!B46,INV!C46,IF(B24=INV!B47,INV!C47,IF(B24=INV!B48,INV!C48,IF(B24=INV!B49,INV!C49,IF(B24=INV!B50,INV!C50,IF(B24=INV!B51,INV!C51,IF(B24=INV!B52,INV!C52,IF(B24=INV!B53,INV!C53,IF(B24=INV!B54,INV!C54)))))))))))))))))))))))))))))))))))))))))))))))))))))) | D24: =IF(C24="","",IF(C24=INV!C2,INV!D2,IF(C24=INV!C3,INV!D3,IF(C24=INV!C4,INV!D4,IF(C24=INV!C5,INV!D5,IF(C24=INV!C6,INV!D6,IF(C24=INV!C7,INV!D7,IF(C24=INV!C8,INV!D8,IF(C24=INV!C9,INV!D9,IF(C24=INV!C10,INV!D10,IF(C24=INV!C11,INV!D11,IF(C24=INV!C12,INV!D12,IF(C24=INV!C13,INV!D13,IF(C24=INV!C14,INV!D14,IF(C24=INV!C15,INV!D15,IF(C24=INV!C16,INV!D16,IF(C24=INV!C17,INV!D17,IF(C24=INV!C18,INV!D18,IF(C24=INV!C19,INV!D19,IF(C24=INV!C20,INV!D20,IF(C24=INV!C21,INV!D21,IF(C24=INV!C22,INV!D22,IF(C24=INV!C23,INV!D23,IF(C24=INV!C24,INV!D24,IF(C24=INV!C25,INV!D25,IF(C24=INV!C26,INV!D26,IF(C24=INV!C27,INV!D27,IF(C24=INV!C28,INV!D28,IF(C24=INV!C29,INV!D29,IF(C24=INV!C30,INV!D30,IF(C24=INV!C31,INV!D31,IF(C24=INV!C32,INV!D32,IF(C24=INV!C33,INV!D33,IF(C24=INV!C34,INV!D34,IF(C24=INV!C35,INV!D325,IF(C24=INV!C36,INV!D36,IF(C24=INV!C37,INV!D37,IF(C24=INV!C38,INV!D38,IF(C24=INV!C39,INV!D39,IF(C24=INV!C40,INV!D40,IF(C24=INV!C41,INV!D41,IF(C24=INV!C42,INV!D42,IF(C24=INV!C43,INV!D43,IF(C24=INV!C44,INV!D44,IF(C24=INV!C45,INV!D45,IF(C24=INV!C46,INV!D46,IF(C24=INV!C47,INV!D47,IF(C24=INV!C48,INV!D48,IF(C24=INV!C49,INV!D49,IF(C24=INV!C50,INV!D50,IF(C24=INV!C51,INV!D51,IF(C24=INV!C52,INV!D52,IF(C24=INV!C53,INV!D53,IF(C24=INV!C54,INV!D54)))))))))))))))))))))))))))))))))))))))))))))))))))))) | G24: =IF(B24="","",IF(B24=INV!B2,INV!F2,IF(B24=INV!B3,INV!F3,IF(B24=INV!B4,INV!F4,IF(B24=INV!B5,INV!F5,IF(B24=INV!B6,INV!F6,IF(B24=INV!B7,INV!F7,IF(B24=INV!B8,INV!F8,IF(B24=INV!B9,INV!F9,IF(B24=INV!B10,INV!F10,IF(B24=INV!B11,INV!F11,IF(B24=INV!B12,INV!F12,IF(B24=INV!B13,INV!F13,IF(B24=INV!B14,INV!F14,IF(B24=INV!B15,INV!F15,IF(B24=INV!B16,INV!F16,IF(B24=INV!B17,INV!F17,IF(B24=INV!B18,INV!F18,IF(B24=INV!B19,INV!F19,IF(B24=INV!B20,INV!F20,IF(B24=INV!B21,INV!F21,IF(B24=INV!B22,INV!F22,IF(B24=INV!B23,INV!F23,IF(B24=INV!B24,INV!F24,IF(B24=INV!B25,INV!F25,IF(B24=INV!B26,INV!F26,IF(B24=INV!B27,INV!F27,IF(B24=INV!B28,INV!F28,IF(B24=INV!B29,INV!F29,IF(B24=INV!B30,INV!F30,IF(B24=INV!B31,INV!F31,IF(B24=INV!B32,INV!F32,IF(B24=INV!B33,INV!F33,IF(B24=INV!B34,INV!F34,IF(B24=INV!B35,INV!F35,IF(B24=INV!B36,INV!F36,IF(B24=INV!B37,INV!F37,IF(B24=INV!B38,INV!F38,IF(B24=INV!B39,INV!F39,IF(B24=INV!B40,INV!F40,IF(B24=INV!B41,INV!F41,IF(B24=INV!B42,INV!F42,IF(B24=INV!B43,INV!F43,IF(B24=INV!B44,INV!F44,IF(B24=INV!B45,INV!F45,IF(B24=INV!B46,INV!F46,IF(B24=INV!B47,INV!F47,IF(B24=INV!B48,INV!F48,IF(B24=INV!B49,INV!F49,IF(B24=INV!B50,INV!F50,IF(B24=INV!B51,INV!F51,IF(B24=INV!B52,INV!F52,IF(B24=INV!B54,INV!F54))))))))))))))))))))))))))))))))))))))))))))))))))))) | H24: =IF(F24="","",G24*F24)
C25: =IF(B25="","",IF(B25=INV!B2,INV!C2,IF(B25=INV!B3,INV!C3,IF(B25=INV!B4,INV!C4,IF(B25=INV!B5,INV!C5,IF(B25=INV!B6,INV!C6,IF(B25=INV!B7,INV!C7,IF(B25=INV!B8,INV!C8,IF(B25=INV!B9,INV!C9,IF(B25=INV!B10,INV!C10,IF(B25=INV!B11,INV!C11,IF(B25=INV!B12,INV!C12,IF(B25=INV!B13,INV!C13,IF(B25=INV!B14,INV!C14,IF(B25=INV!B15,INV!C15,IF(B25=INV!B16,INV!C16,IF(B25=INV!B17,INV!C17,IF(B25=INV!B18,INV!C18,IF(B25=INV!B19,INV!C19,IF(B25=INV!B20,INV!C20,IF(B25=INV!B21,INV!C21,IF(B25=INV!B22,INV!C22,IF(B25=INV!B23,INV!C23,IF(B25=INV!B24,INV!C24,IF(B25=INV!B25,INV!C25,IF(B25=INV!B26,INV!C26,IF(B25=INV!B27,INV!C27,IF(B25=INV!B28,INV!C28,IF(B25=INV!B29,INV!C29,IF(B25=INV!B30,INV!C30,IF(B25=INV!B31,INV!C31,IF(B25=INV!B32,INV!C32,IF(B25=INV!B33,INV!C33,IF(B25=INV!B34,INV!C34,IF(B25=INV!B35,INV!C35,IF(B25=INV!B36,INV!C326,IF(B25=INV!B37,INV!C37,IF(B25=INV!B38,INV!C38,IF(B25=INV!B39,INV!C39,IF(B25=INV!B40,INV!C40,IF(B25=INV!B41,INV!C41,IF(B25=INV!B42,INV!C42,IF(B25=INV!B43,INV!C43,IF(B25=INV!B44,INV!C44,IF(B25=INV!B45,INV!C45,IF(B25=INV!B46,INV!C46,IF(B25=INV!B47,INV!C47,IF(B25=INV!B48,INV!C48,IF(B25=INV!B49,INV!C49,IF(B25=INV!B50,INV!C50,IF(B25=INV!B51,INV!C51,IF(B25=INV!B52,INV!C52,IF(B25=INV!B53,INV!C53,IF(B25=INV!B54,INV!C54,IF(B25=INV!B55,INV!C55))))))))))))))))))))))))))))))))))))))))))))))))))))))) | D25: =IF(C25="","",IF(C25=INV!C2,INV!D2,IF(C25=INV!C3,INV!D3,IF(C25=INV!C4,INV!D4,IF(C25=INV!C5,INV!D5,IF(C25=INV!C6,INV!D6,IF(C25=INV!C7,INV!D7,IF(C25=INV!C8,INV!D8,IF(C25=INV!C9,INV!D9,IF(C25=INV!C10,INV!D10,IF(C25=INV!C11,INV!D11,IF(C25=INV!C12,INV!D12,IF(C25=INV!C13,INV!D13,IF(C25=INV!C14,INV!D14,IF(C25=INV!C15,INV!D15,IF(C25=INV!C16,INV!D16,IF(C25=INV!C17,INV!D17,IF(C25=INV!C18,INV!D18,IF(C25=INV!C19,INV!D19,IF(C25=INV!C20,INV!D20,IF(C25=INV!C21,INV!D21,IF(C25=INV!C22,INV!D22,IF(C25=INV!C23,INV!D23,IF(C25=INV!C24,INV!D24,IF(C25=INV!C25,INV!D25,IF(C25=INV!C26,INV!D26,IF(C25=INV!C27,INV!D27,IF(C25=INV!C28,INV!D28,IF(C25=INV!C29,INV!D29,IF(C25=INV!C30,INV!D30,IF(C25=INV!C31,INV!D31,IF(C25=INV!C32,INV!D32,IF(C25=INV!C33,INV!D33,IF(C25=INV!C34,INV!D34,IF(C25=INV!C35,INV!D35,IF(C25=INV!C36,INV!D326,IF(C25=INV!C37,INV!D37,IF(C25=INV!C38,INV!D38,IF(C25=INV!C39,INV!D39,IF(C25=INV!C40,INV!D40,IF(C25=INV!C41,INV!D41,IF(C25=INV!C42,INV!D42,IF(C25=INV!C43,INV!D43,IF(C25=INV!C44,INV!D44,IF(C25=INV!C45,INV!D45,IF(C25=INV!C46,INV!D46,IF(C25=INV!C47,INV!D47,IF(C25=INV!C48,INV!D48,IF(C25=INV!C49,INV!D49,IF(C25=INV!C50,INV!D50,IF(C25=INV!C51,INV!D51,IF(C25=INV!C52,INV!D52,IF(C25=INV!C53,INV!D53,IF(C25=INV!C54,INV!D54,IF(C25=INV!C55,INV!D55))))))))))))))))))))))))))))))))))))))))))))))))))))))) | G25: =IF(B25="","",IF(B25=INV!B2,INV!F2,IF(B25=INV!B3,INV!F3,IF(B25=INV!B4,INV!F4,IF(B25=INV!B5,INV!F5,IF(B25=INV!B6,INV!F6,IF(B25=INV!B7,INV!F7,IF(B25=INV!B8,INV!F8,IF(B25=INV!B9,INV!F9,IF(B25=INV!B10,INV!F10,IF(B25=INV!B11,INV!F11,IF(B25=INV!B12,INV!F12,IF(B25=INV!B13,INV!F13,IF(B25=INV!B14,INV!F14,IF(B25=INV!B15,INV!F15,IF(B25=INV!B16,INV!F16,IF(B25=INV!B17,INV!F17,IF(B25=INV!B18,INV!F18,IF(B25=INV!B19,INV!F19,IF(B25=INV!B20,INV!F20,IF(B25=INV!B21,INV!F21,IF(B25=INV!B22,INV!F22,IF(B25=INV!B23,INV!F23,IF(B25=INV!B24,INV!F24,IF(B25=INV!B25,INV!F25,IF(B25=INV!B26,INV!F26,IF(B25=INV!B27,INV!F27,IF(B25=INV!B28,INV!F28,IF(B25=INV!B29,INV!F29,IF(B25=INV!B30,INV!F30,IF(B25=INV!B31,INV!F31,IF(B25=INV!B32,INV!F32,IF(B25=INV!B33,INV!F33,IF(B25=INV!B34,INV!F34,IF(B25=INV!B35,INV!F35,IF(B25=INV!B36,INV!F36,IF(B25=INV!B37,INV!F37,IF(B25=INV!B38,INV!F38,IF(B25=INV!B39,INV!F39,IF(B25=INV!B40,INV!F40,IF(B25=INV!B41,INV!F41,IF(B25=INV!B42,INV!F42,IF(B25=INV!B43,INV!F43,IF(B25=INV!B44,INV!F44,IF(B25=INV!B45,INV!F45,IF(B25=INV!B46,INV!F46,IF(B25=INV!B47,INV!F47,IF(B25=INV!B48,INV!F48,IF(B25=INV!B49,INV!F49,IF(B25=INV!B50,INV!F50,IF(B25=INV!B51,INV!F51,IF(B25=INV!B52,INV!F52,IF(B25=INV!B53,INV!F53,IF(B25=INV!B55,INV!F55)))))))))))))))))))))))))))))))))))))))))))))))))))))) | H25: =IF(F25="","",G25*F25)
C26: =IF(B26="","",IF(B26=INV!B2,INV!C2,IF(B26=INV!B3,INV!C3,IF(B26=INV!B4,INV!C4,IF(B26=INV!B5,INV!C5,IF(B26=INV!B6,INV!C6,IF(B26=INV!B7,INV!C7,IF(B26=INV!B8,INV!C8,IF(B26=INV!B9,INV!C9,IF(B26=INV!B10,INV!C10,IF(B26=INV!B11,INV!C11,IF(B26=INV!B12,INV!C12,IF(B26=INV!B13,INV!C13,IF(B26=INV!B14,INV!C14,IF(B26=INV!B15,INV!C15,IF(B26=INV!B16,INV!C16,IF(B26=INV!B17,INV!C17,IF(B26=INV!B18,INV!C18,IF(B26=INV!B19,INV!C19,IF(B26=INV!B20,INV!C20,IF(B26=INV!B21,INV!C21,IF(B26=INV!B22,INV!C22,IF(B26=INV!B23,INV!C23,IF(B26=INV!B24,INV!C24,IF(B26=INV!B25,INV!C25,IF(B26=INV!B26,INV!C26,IF(B26=INV!B27,INV!C27,IF(B26=INV!B28,INV!C28,IF(B26=INV!B29,INV!C29,IF(B26=INV!B30,INV!C30,IF(B26=INV!B31,INV!C31,IF(B26=INV!B32,INV!C32,IF(B26=INV!B33,INV!C33,IF(B26=INV!B34,INV!C34,IF(B26=INV!B35,INV!C35,IF(B26=INV!B36,INV!C36,IF(B26=INV!B37,INV!C327,IF(B26=INV!B38,INV!C38,IF(B26=INV!B39,INV!C39,IF(B26=INV!B40,INV!C40,IF(B26=INV!B41,INV!C41,IF(B26=INV!B42,INV!C42,IF(B26=INV!B43,INV!C43,IF(B26=INV!B44,INV!C44,IF(B26=INV!B45,INV!C45,IF(B26=INV!B46,INV!C46,IF(B26=INV!B47,INV!C47,IF(B26=INV!B48,INV!C48,IF(B26=INV!B49,INV!C49,IF(B26=INV!B50,INV!C50,IF(B26=INV!B51,INV!C51,IF(B26=INV!B52,INV!C52,IF(B26=INV!B53,INV!C53,IF(B26=INV!B54,INV!C54,IF(B26=INV!B55,INV!C55,IF(B26=INV!B56,INV!C56)))))))))))))))))))))))))))))))))))))))))))))))))))))))) | D26: =IF(C26="","",IF(C26=INV!C2,INV!D2,IF(C26=INV!C3,INV!D3,IF(C26=INV!C4,INV!D4,IF(C26=INV!C5,INV!D5,IF(C26=INV!C6,INV!D6,IF(C26=INV!C7,INV!D7,IF(C26=INV!C8,INV!D8,IF(C26=INV!C9,INV!D9,IF(C26=INV!C10,INV!D10,IF(C26=INV!C11,INV!D11,IF(C26=INV!C12,INV!D12,IF(C26=INV!C13,INV!D13,IF(C26=INV!C14,INV!D14,IF(C26=INV!C15,INV!D15,IF(C26=INV!C16,INV!D16,IF(C26=INV!C17,INV!D17,IF(C26=INV!C18,INV!D18,IF(C26=INV!C19,INV!D19,IF(C26=INV!C20,INV!D20,IF(C26=INV!C21,INV!D21,IF(C26=INV!C22,INV!D22,IF(C26=INV!C23,INV!D23,IF(C26=INV!C24,INV!D24,IF(C26=INV!C25,INV!D25,IF(C26=INV!C26,INV!D26,IF(C26=INV!C27,INV!D27,IF(C26=INV!C28,INV!D28,IF(C26=INV!C29,INV!D29,IF(C26=INV!C30,INV!D30,IF(C26=INV!C31,INV!D31,IF(C26=INV!C32,INV!D32,IF(C26=INV!C33,INV!D33,IF(C26=INV!C34,INV!D34,IF(C26=INV!C35,INV!D35,IF(C26=INV!C36,INV!D36,IF(C26=INV!C37,INV!D327,IF(C26=INV!C38,INV!D38,IF(C26=INV!C39,INV!D39,IF(C26=INV!C40,INV!D40,IF(C26=INV!C41,INV!D41,IF(C26=INV!C42,INV!D42,IF(C26=INV!C43,INV!D43,IF(C26=INV!C44,INV!D44,IF(C26=INV!C45,INV!D45,IF(C26=INV!C46,INV!D46,IF(C26=INV!C47,INV!D47,IF(C26=INV!C48,INV!D48,IF(C26=INV!C49,INV!D49,IF(C26=INV!C50,INV!D50,IF(C26=INV!C51,INV!D51,IF(C26=INV!C52,INV!D52,IF(C26=INV!C53,INV!D53,IF(C26=INV!C54,INV!D54,IF(C26=INV!C55,INV!D55,IF(C26=INV!C56,INV!D56)))))))))))))))))))))))))))))))))))))))))))))))))))))))) | G26: =IF(B26="","",IF(B26=INV!B2,INV!F2,IF(B26=INV!B3,INV!F3,IF(B26=INV!B4,INV!F4,IF(B26=INV!B5,INV!F5,IF(B26=INV!B6,INV!F6,IF(B26=INV!B7,INV!F7,IF(B26=INV!B8,INV!F8,IF(B26=INV!B9,INV!F9,IF(B26=INV!B10,INV!F10,IF(B26=INV!B11,INV!F11,IF(B26=INV!B12,INV!F12,IF(B26=INV!B13,INV!F13,IF(B26=INV!B14,INV!F14,IF(B26=INV!B15,INV!F15,IF(B26=INV!B16,INV!F16,IF(B26=INV!B17,INV!F17,IF(B26=INV!B18,INV!F18,IF(B26=INV!B19,INV!F19,IF(B26=INV!B20,INV!F20,IF(B26=INV!B21,INV!F21,IF(B26=INV!B22,INV!F22,IF(B26=INV!B23,INV!F23,IF(B26=INV!B24,INV!F24,IF(B26=INV!B25,INV!F25,IF(B26=INV!B26,INV!F26,IF(B26=INV!B27,INV!F27,IF(B26=INV!B28,INV!F28,IF(B26=INV!B29,INV!F29,IF(B26=INV!B30,INV!F30,IF(B26=INV!B31,INV!F31,IF(B26=INV!B32,INV!F32,IF(B26=INV!B33,INV!F33,IF(B26=INV!B34,INV!F34,IF(B26=INV!B35,INV!F35,IF(B26=INV!B36,INV!F36,IF(B26=INV!B37,INV!F37,IF(B26=INV!B38,INV!F38,IF(B26=INV!B39,INV!F39,IF(B26=INV!B40,INV!F40,IF(B26=INV!B41,INV!F41,IF(B26=INV!B42,INV!F42,IF(B26=INV!B43,INV!F43,IF(B26=INV!B44,INV!F44,IF(B26=INV!B45,INV!F45,IF(B26=INV!B46,INV!F46,IF(B26=INV!B47,INV!F47,IF(B26=INV!B48,INV!F48,IF(B26=INV!B49,INV!F49,IF(B26=INV!B50,INV!F50,IF(B26=INV!B51,INV!F51,IF(B26=INV!B52,INV!F52,IF(B26=INV!B53,INV!F53,IF(B26=INV!B54,INV!F54,IF(B26=INV!B56,INV!F56))))))))))))))))))))))))))))))))))))))))))))))))))))))) | H26: =IF(F26="","",G26*F26)
C27: =IF(B27="","",IF(B27=INV!B2,INV!C2,IF(B27=INV!B3,INV!C3,IF(B27=INV!B4,INV!C4,IF(B27=INV!B5,INV!C5,IF(B27=INV!B6,INV!C6,IF(B27=INV!B7,INV!C7,IF(B27=INV!B8,INV!C8,IF(B27=INV!B9,INV!C9,IF(B27=INV!B10,INV!C10,IF(B27=INV!B11,INV!C11,IF(B27=INV!B12,INV!C12,IF(B27=INV!B13,INV!C13,IF(B27=INV!B14,INV!C14,IF(B27=INV!B15,INV!C15,IF(B27=INV!B16,INV!C16,IF(B27=INV!B17,INV!C17,IF(B27=INV!B18,INV!C18,IF(B27=INV!B19,INV!C19,IF(B27=INV!B20,INV!C20,IF(B27=INV!B21,INV!C21,IF(B27=INV!B22,INV!C22,IF(B27=INV!B23,INV!C23,IF(B27=INV!B24,INV!C24,IF(B27=INV!B25,INV!C25,IF(B27=INV!B26,INV!C26,IF(B27=INV!B27,INV!C27,IF(B27=INV!B28,INV!C28,IF(B27=INV!B29,INV!C29,IF(B27=INV!B30,INV!C30,IF(B27=INV!B31,INV!C31,IF(B27=INV!B32,INV!C32,IF(B27=INV!B33,INV!C33,IF(B27=INV!B34,INV!C34,IF(B27=INV!B35,INV!C35,IF(B27=INV!B36,INV!C36,IF(B27=INV!B37,INV!C37,IF(B27=INV!B38,INV!C328,IF(B27=INV!B39,INV!C39,IF(B27=INV!B40,INV!C40,IF(B27=INV!B41,INV!C41,IF(B27=INV!B42,INV!C42,IF(B27=INV!B43,INV!C43,IF(B27=INV!B44,INV!C44,IF(B27=INV!B45,INV!C45,IF(B27=INV!B46,INV!C46,IF(B27=INV!B47,INV!C47,IF(B27=INV!B48,INV!C48,IF(B27=INV!B49,INV!C49,IF(B27=INV!B50,INV!C50,IF(B27=INV!B51,INV!C51,IF(B27=INV!B52,INV!C52,IF(B27=INV!B53,INV!C53,IF(B27=INV!B54,INV!C54,IF(B27=INV!B55,INV!C55,IF(B27=INV!B56,INV!C56,IF(B27=INV!B57,INV!C57))))))))))))))))))))))))))))))))))))))))))))))))))))))))) | D27: =IF(C27="","",IF(C27=INV!C2,INV!D2,IF(C27=INV!C3,INV!D3,IF(C27=INV!C4,INV!D4,IF(C27=INV!C5,INV!D5,IF(C27=INV!C6,INV!D6,IF(C27=INV!C7,INV!D7,IF(C27=INV!C8,INV!D8,IF(C27=INV!C9,INV!D9,IF(C27=INV!C10,INV!D10,IF(C27=INV!C11,INV!D11,IF(C27=INV!C12,INV!D12,IF(C27=INV!C13,INV!D13,IF(C27=INV!C14,INV!D14,IF(C27=INV!C15,INV!D15,IF(C27=INV!C16,INV!D16,IF(C27=INV!C17,INV!D17,IF(C27=INV!C18,INV!D18,IF(C27=INV!C19,INV!D19,IF(C27=INV!C20,INV!D20,IF(C27=INV!C21,INV!D21,IF(C27=INV!C22,INV!D22,IF(C27=INV!C23,INV!D23,IF(C27=INV!C24,INV!D24,IF(C27=INV!C25,INV!D25,IF(C27=INV!C26,INV!D26,IF(C27=INV!C27,INV!D27,IF(C27=INV!C28,INV!D28,IF(C27=INV!C29,INV!D29,IF(C27=INV!C30,INV!D30,IF(C27=INV!C31,INV!D31,IF(C27=INV!C32,INV!D32,IF(C27=INV!C33,INV!D33,IF(C27=INV!C34,INV!D34,IF(C27=INV!C35,INV!D35,IF(C27=INV!C36,INV!D36,IF(C27=INV!C37,INV!D37,IF(C27=INV!C38,INV!D328,IF(C27=INV!C39,INV!D39,IF(C27=INV!C40,INV!D40,IF(C27=INV!C41,INV!D41,IF(C27=INV!C42,INV!D42,IF(C27=INV!C43,INV!D43,IF(C27=INV!C44,INV!D44,IF(C27=INV!C45,INV!D45,IF(C27=INV!C46,INV!D46,IF(C27=INV!C47,INV!D47,IF(C27=INV!C48,INV!D48,IF(C27=INV!C49,INV!D49,IF(C27=INV!C50,INV!D50,IF(C27=INV!C51,INV!D51,IF(C27=INV!C52,INV!D52,IF(C27=INV!C53,INV!D53,IF(C27=INV!C54,INV!D54,IF(C27=INV!C55,INV!D55,IF(C27=INV!C56,INV!D56,IF(C27=INV!C57,INV!D57))))))))))))))))))))))))))))))))))))))))))))))))))))))))) | G27: =IF(B27="","",IF(B27=INV!B2,INV!F2,IF(B27=INV!B3,INV!F3,IF(B27=INV!B4,INV!F4,IF(B27=INV!B5,INV!F5,IF(B27=INV!B6,INV!F6,IF(B27=INV!B7,INV!F7,IF(B27=INV!B8,INV!F8,IF(B27=INV!B9,INV!F9,IF(B27=INV!B10,INV!F10,IF(B27=INV!B11,INV!F11,IF(B27=INV!B12,INV!F12,IF(B27=INV!B13,INV!F13,IF(B27=INV!B14,INV!F14,IF(B27=INV!B15,INV!F15,IF(B27=INV!B16,INV!F16,IF(B27=INV!B17,INV!F17,IF(B27=INV!B18,INV!F18,IF(B27=INV!B19,INV!F19,IF(B27=INV!B20,INV!F20,IF(B27=INV!B21,INV!F21,IF(B27=INV!B22,INV!F22,IF(B27=INV!B23,INV!F23,IF(B27=INV!B24,INV!F24,IF(B27=INV!B25,INV!F25,IF(B27=INV!B26,INV!F26,IF(B27=INV!B27,INV!F27,IF(B27=INV!B28,INV!F28,IF(B27=INV!B29,INV!F29,IF(B27=INV!B30,INV!F30,IF(B27=INV!B31,INV!F31,IF(B27=INV!B32,INV!F32,IF(B27=INV!B33,INV!F33,IF(B27=INV!B34,INV!F34,IF(B27=INV!B35,INV!F35,IF(B27=INV!B36,INV!F36,IF(B27=INV!B37,INV!F37,IF(B27=INV!B38,INV!F38,IF(B27=INV!B39,INV!F39,IF(B27=INV!B40,INV!F40,IF(B27=INV!B41,INV!F41,IF(B27=INV!B42,INV!F42,IF(B27=INV!B43,INV!F43,IF(B27=INV!B44,INV!F44,IF(B27=INV!B45,INV!F45,IF(B27=INV!B46,INV!F46,IF(B27=INV!B47,INV!F47,IF(B27=INV!B48,INV!F48,IF(B27=INV!B49,INV!F49,IF(B27=INV!B50,INV!F50,IF(B27=INV!B51,INV!F51,IF(B27=INV!B52,INV!F52,IF(B27=INV!B53,INV!F53,IF(B27=INV!B54,INV!F54,IF(B27=INV!B55,INV!F55,IF(B27=INV!B57,INV!F57)))))))))))))))))))))))))))))))))))))))))))))))))))))))) | H27: =IF(F27="","",G27*F27)
C28: =IF(B28="","",IF(B28=INV!B2,INV!C2,IF(B28=INV!B3,INV!C3,IF(B28=INV!B4,INV!C4,IF(B28=INV!B5,INV!C5,IF(B28=INV!B6,INV!C6,IF(B28=INV!B7,INV!C7,IF(B28=INV!B8,INV!C8,IF(B28=INV!B9,INV!C9,IF(B28=INV!B10,INV!C10,IF(B28=INV!B11,INV!C11,IF(B28=INV!B12,INV!C12,IF(B28=INV!B13,INV!C13,IF(B28=INV!B14,INV!C14,IF(B28=INV!B15,INV!C15,IF(B28=INV!B16,INV!C16,IF(B28=INV!B17,INV!C17,IF(B28=INV!B18,INV!C18,IF(B28=INV!B19,INV!C19,IF(B28=INV!B20,INV!C20,IF(B28=INV!B21,INV!C21,IF(B28=INV!B22,INV!C22,IF(B28=INV!B23,INV!C23,IF(B28=INV!B24,INV!C24,IF(B28=INV!B25,INV!C25,IF(B28=INV!B26,INV!C26,IF(B28=INV!B27,INV!C27,IF(B28=INV!B28,INV!C28,IF(B28=INV!B29,INV!C29,IF(B28=INV!B30,INV!C30,IF(B28=INV!B31,INV!C31,IF(B28=INV!B32,INV!C32,IF(B28=INV!B33,INV!C33,IF(B28=INV!B34,INV!C34,IF(B28=INV!B35,INV!C35,IF(B28=INV!B36,INV!C36,IF(B28=INV!B37,INV!C37,IF(B28=INV!B38,INV!C38,IF(B28=INV!B39,INV!C329,IF(B28=INV!B40,INV!C40,IF(B28=INV!B41,INV!C41,IF(B28=INV!B42,INV!C42,IF(B28=INV!B43,INV!C43,IF(B28=INV!B44,INV!C44,IF(B28=INV!B45,INV!C45,IF(B28=INV!B46,INV!C46,IF(B28=INV!B47,INV!C47,IF(B28=INV!B48,INV!C48,IF(B28=INV!B49,INV!C49,IF(B28=INV!B50,INV!C50,IF(B28=INV!B51,INV!C51,IF(B28=INV!B52,INV!C52,IF(B28=INV!B53,INV!C53,IF(B28=INV!B54,INV!C54,IF(B28=INV!B55,INV!C55,IF(B28=INV!B56,INV!C56,IF(B28=INV!B57,INV!C57,IF(B28=INV!B58,INV!C58)))))))))))))))))))))))))))))))))))))))))))))))))))))))))) | D28: =IF(C28="","",IF(C28=INV!C2,INV!D2,IF(C28=INV!C3,INV!D3,IF(C28=INV!C4,INV!D4,IF(C28=INV!C5,INV!D5,IF(C28=INV!C6,INV!D6,IF(C28=INV!C7,INV!D7,IF(C28=INV!C8,INV!D8,IF(C28=INV!C9,INV!D9,IF(C28=INV!C10,INV!D10,IF(C28=INV!C11,INV!D11,IF(C28=INV!C12,INV!D12,IF(C28=INV!C13,INV!D13,IF(C28=INV!C14,INV!D14,IF(C28=INV!C15,INV!D15,IF(C28=INV!C16,INV!D16,IF(C28=INV!C17,INV!D17,IF(C28=INV!C18,INV!D18,IF(C28=INV!C19,INV!D19,IF(C28=INV!C20,INV!D20,IF(C28=INV!C21,INV!D21,IF(C28=INV!C22,INV!D22,IF(C28=INV!C23,INV!D23,IF(C28=INV!C24,INV!D24,IF(C28=INV!C25,INV!D25,IF(C28=INV!C26,INV!D26,IF(C28=INV!C27,INV!D27,IF(C28=INV!C28,INV!D28,IF(C28=INV!C29,INV!D29,IF(C28=INV!C30,INV!D30,IF(C28=INV!C31,INV!D31,IF(C28=INV!C32,INV!D32,IF(C28=INV!C33,INV!D33,IF(C28=INV!C34,INV!D34,IF(C28=INV!C35,INV!D35,IF(C28=INV!C36,INV!D36,IF(C28=INV!C37,INV!D37,IF(C28=INV!C38,INV!D38,IF(C28=INV!C39,INV!D329,IF(C28=INV!C40,INV!D40,IF(C28=INV!C41,INV!D41,IF(C28=INV!C42,INV!D42,IF(C28=INV!C43,INV!D43,IF(C28=INV!C44,INV!D44,IF(C28=INV!C45,INV!D45,IF(C28=INV!C46,INV!D46,IF(C28=INV!C47,INV!D47,IF(C28=INV!C48,INV!D48,IF(C28=INV!C49,INV!D49,IF(C28=INV!C50,INV!D50,IF(C28=INV!C51,INV!D51,IF(C28=INV!C52,INV!D52,IF(C28=INV!C53,INV!D53,IF(C28=INV!C54,INV!D54,IF(C28=INV!C55,INV!D55,IF(C28=INV!C56,INV!D56,IF(C28=INV!C57,INV!D57,IF(C28=INV!C58,INV!D58)))))))))))))))))))))))))))))))))))))))))))))))))))))))))) | G28: =IF(B28="","",IF(B28=INV!B2,INV!F2,IF(B28=INV!B3,INV!F3,IF(B28=INV!B4,INV!F4,IF(B28=INV!B5,INV!F5,IF(B28=INV!B6,INV!F6,IF(B28=INV!B7,INV!F7,IF(B28=INV!B8,INV!F8,IF(B28=INV!B9,INV!F9,IF(B28=INV!B10,INV!F10,IF(B28=INV!B11,INV!F11,IF(B28=INV!B12,INV!F12,IF(B28=INV!B13,INV!F13,IF(B28=INV!B14,INV!F14,IF(B28=INV!B15,INV!F15,IF(B28=INV!B16,INV!F16,IF(B28=INV!B17,INV!F17,IF(B28=INV!B18,INV!F18,IF(B28=INV!B19,INV!F19,IF(B28=INV!B20,INV!F20,IF(B28=INV!B21,INV!F21,IF(B28=INV!B22,INV!F22,IF(B28=INV!B23,INV!F23,IF(B28=INV!B24,INV!F24,IF(B28=INV!B25,INV!F25,IF(B28=INV!B26,INV!F26,IF(B28=INV!B27,INV!F27,IF(B28=INV!B28,INV!F28,IF(B28=INV!B29,INV!F29,IF(B28=INV!B30,INV!F30,IF(B28=INV!B31,INV!F31,IF(B28=INV!B32,INV!F32,IF(B28=INV!B33,INV!F33,IF(B28=INV!B34,INV!F34,IF(B28=INV!B35,INV!F35,IF(B28=INV!B36,INV!F36,IF(B28=INV!B37,INV!F37,IF(B28=INV!B38,INV!F38,IF(B28=INV!B39,INV!F39,IF(B28=INV!B40,INV!F40,IF(B28=INV!B41,INV!F41,IF(B28=INV!B42,INV!F42,IF(B28=INV!B43,INV!F43,IF(B28=INV!B44,INV!F44,IF(B28=INV!B45,INV!F45,IF(B28=INV!B46,INV!F46,IF(B28=INV!B47,INV!F47,IF(B28=INV!B48,INV!F48,IF(B28=INV!B49,INV!F49,IF(B28=INV!B50,INV!F50,IF(B28=INV!B51,INV!F51,IF(B28=INV!B52,INV!F52,IF(B28=INV!B53,INV!F53,IF(B28=INV!B54,INV!F54,IF(B28=INV!B55,INV!F55,IF(B28=INV!B56,INV!F56,IF(B28=INV!B58,INV!F58))))))))))))))))))))))))))))))))))))))))))))))))))))))))) | H28: =IF(F28="","",G28*F28)
C29: =IF(B29="","",IF(B29=INV!B2,INV!C2,IF(B29=INV!B3,INV!C3,IF(B29=INV!B4,INV!C4,IF(B29=INV!B5,INV!C5,IF(B29=INV!B6,INV!C6,IF(B29=INV!B7,INV!C7,IF(B29=INV!B8,INV!C8,IF(B29=INV!B9,INV!C9,IF(B29=INV!B10,INV!C10,IF(B29=INV!B11,INV!C11,IF(B29=INV!B12,INV!C12,IF(B29=INV!B13,INV!C13,IF(B29=INV!B14,INV!C14,IF(B29=INV!B15,INV!C15,IF(B29=INV!B16,INV!C16,IF(B29=INV!B17,INV!C17,IF(B29=INV!B18,INV!C18,IF(B29=INV!B19,INV!C19,IF(B29=INV!B20,INV!C20,IF(B29=INV!B21,INV!C21,IF(B29=INV!B22,INV!C22,IF(B29=INV!B23,INV!C23,IF(B29=INV!B24,INV!C24,IF(B29=INV!B25,INV!C25,IF(B29=INV!B26,INV!C26,IF(B29=INV!B27,INV!C27,IF(B29=INV!B28,INV!C28,IF(B29=INV!B29,INV!C29,IF(B29=INV!B30,INV!C30,IF(B29=INV!B31,INV!C31,IF(B29=INV!B32,INV!C32,IF(B29=INV!B33,INV!C33,IF(B29=INV!B34,INV!C34,IF(B29=INV!B35,INV!C35,IF(B29=INV!B36,INV!C36,IF(B29=INV!B37,INV!C37,IF(B29=INV!B38,INV!C38,IF(B29=INV!B39,INV!C39,IF(B29=INV!B40,INV!C330,IF(B29=INV!B41,INV!C41,IF(B29=INV!B42,INV!C42,IF(B29=INV!B43,INV!C43,IF(B29=INV!B44,INV!C44,IF(B29=INV!B45,INV!C45,IF(B29=INV!B46,INV!C46,IF(B29=INV!B47,INV!C47,IF(B29=INV!B48,INV!C48,IF(B29=INV!B49,INV!C49,IF(B29=INV!B50,INV!C50,IF(B29=INV!B51,INV!C51,IF(B29=INV!B52,INV!C52,IF(B29=INV!B53,INV!C53,IF(B29=INV!B54,INV!C54,IF(B29=INV!B55,INV!C55,IF(B29=INV!B56,INV!C56,IF(B29=INV!B57,INV!C57,IF(B29=INV!B58,INV!C58,IF(B29=INV!B59,INV!C59))))))))))))))))))))))))))))))))))))))))))))))))))))))))))) | D29: =IF(C29="","",IF(C29=INV!C2,INV!D2,IF(C29=INV!C3,INV!D3,IF(C29=INV!C4,INV!D4,IF(C29=INV!C5,INV!D5,IF(C29=INV!C6,INV!D6,IF(C29=INV!C7,INV!D7,IF(C29=INV!C8,INV!D8,IF(C29=INV!C9,INV!D9,IF(C29=INV!C10,INV!D10,IF(C29=INV!C11,INV!D11,IF(C29=INV!C12,INV!D12,IF(C29=INV!C13,INV!D13,IF(C29=INV!C14,INV!D14,IF(C29=INV!C15,INV!D15,IF(C29=INV!C16,INV!D16,IF(C29=INV!C17,INV!D17,IF(C29=INV!C18,INV!D18,IF(C29=INV!C19,INV!D19,IF(C29=INV!C20,INV!D20,IF(C29=INV!C21,INV!D21,IF(C29=INV!C22,INV!D22,IF(C29=INV!C23,INV!D23,IF(C29=INV!C24,INV!D24,IF(C29=INV!C25,INV!D25,IF(C29=INV!C26,INV!D26,IF(C29=INV!C27,INV!D27,IF(C29=INV!C28,INV!D28,IF(C29=INV!C29,INV!D29,IF(C29=INV!C30,INV!D30,IF(C29=INV!C31,INV!D31,IF(C29=INV!C32,INV!D32,IF(C29=INV!C33,INV!D33,IF(C29=INV!C34,INV!D34,IF(C29=INV!C35,INV!D35,IF(C29=INV!C36,INV!D36,IF(C29=INV!C37,INV!D37,IF(C29=INV!C38,INV!D38,IF(C29=INV!C39,INV!D39,IF(C29=INV!C40,INV!D330,IF(C29=INV!C41,INV!D41,IF(C29=INV!C42,INV!D42,IF(C29=INV!C43,INV!D43,IF(C29=INV!C44,INV!D44,IF(C29=INV!C45,INV!D45,IF(C29=INV!C46,INV!D46,IF(C29=INV!C47,INV!D47,IF(C29=INV!C48,INV!D48,IF(C29=INV!C49,INV!D49,IF(C29=INV!C50,INV!D50,IF(C29=INV!C51,INV!D51,IF(C29=INV!C52,INV!D52,IF(C29=INV!C53,INV!D53,IF(C29=INV!C54,INV!D54,IF(C29=INV!C55,INV!D55,IF(C29=INV!C56,INV!D56,IF(C29=INV!C57,INV!D57,IF(C29=INV!C58,INV!D58,IF(C29=INV!C59,INV!D59))))))))))))))))))))))))))))))))))))))))))))))))))))))))))) | G29: =IF(B29="","",IF(B29=INV!B2,INV!F2,IF(B29=INV!B3,INV!F3,IF(B29=INV!B4,INV!F4,IF(B29=INV!B5,INV!F5,IF(B29=INV!B6,INV!F6,IF(B29=INV!B7,INV!F7,IF(B29=INV!B8,INV!F8,IF(B29=INV!B9,INV!F9,IF(B29=INV!B10,INV!F10,IF(B29=INV!B11,INV!F11,IF(B29=INV!B12,INV!F12,IF(B29=INV!B13,INV!F13,IF(B29=INV!B14,INV!F14,IF(B29=INV!B15,INV!F15,IF(B29=INV!B16,INV!F16,IF(B29=INV!B17,INV!F17,IF(B29=INV!B18,INV!F18,IF(B29=INV!B19,INV!F19,IF(B29=INV!B20,INV!F20,IF(B29=INV!B21,INV!F21,IF(B29=INV!B22,INV!F22,IF(B29=INV!B23,INV!F23,IF(B29=INV!B24,INV!F24,IF(B29=INV!B25,INV!F25,IF(B29=INV!B26,INV!F26,IF(B29=INV!B27,INV!F27,IF(B29=INV!B28,INV!F28,IF(B29=INV!B29,INV!F29,IF(B29=INV!B30,INV!F30,IF(B29=INV!B31,INV!F31,IF(B29=INV!B32,INV!F32,IF(B29=INV!B33,INV!F33,IF(B29=INV!B34,INV!F34,IF(B29=INV!B35,INV!F35,IF(B29=INV!B36,INV!F36,IF(B29=INV!B37,INV!F37,IF(B29=INV!B38,INV!F38,IF(B29=INV!B39,INV!F39,IF(B29=INV!B40,INV!F40,IF(B29=INV!B41,INV!F41,IF(B29=INV!B42,INV!F42,IF(B29=INV!B43,INV!F43,IF(B29=INV!B44,INV!F44,IF(B29=INV!B45,INV!F45,IF(B29=INV!B46,INV!F46,IF(B29=INV!B47,INV!F47,IF(B29=INV!B48,INV!F48,IF(B29=INV!B49,INV!F49,IF(B29=INV!B50,INV!F50,IF(B29=INV!B51,INV!F51,IF(B29=INV!B52,INV!F52,IF(B29=INV!B53,INV!F53,IF(B29=INV!B54,INV!F54,IF(B29=INV!B55,INV!F55,IF(B29=INV!B56,INV!F56,IF(B29=INV!B57,INV!F57,IF(B29=INV!B59,INV!F59)))))))))))))))))))))))))))))))))))))))))))))))))))))))))) | H29: =IF(F29="","",G29*F29)
C30: =IF(B30="","",IF(B30=INV!B2,INV!C2,IF(B30=INV!B3,INV!C3,IF(B30=INV!B4,INV!C4,IF(B30=INV!B5,INV!C5,IF(B30=INV!B6,INV!C6,IF(B30=INV!B7,INV!C7,IF(B30=INV!B8,INV!C8,IF(B30=INV!B9,INV!C9,IF(B30=INV!B10,INV!C10,IF(B30=INV!B11,INV!C11,IF(B30=INV!B12,INV!C12,IF(B30=INV!B13,INV!C13,IF(B30=INV!B14,INV!C14,IF(B30=INV!B15,INV!C15,IF(B30=INV!B16,INV!C16,IF(B30=INV!B17,INV!C17,IF(B30=INV!B18,INV!C18,IF(B30=INV!B19,INV!C19,IF(B30=INV!B20,INV!C20,IF(B30=INV!B21,INV!C21,IF(B30=INV!B22,INV!C22,IF(B30=INV!B23,INV!C23,IF(B30=INV!B24,INV!C24,IF(B30=INV!B25,INV!C25,IF(B30=INV!B26,INV!C26,IF(B30=INV!B27,INV!C27,IF(B30=INV!B28,INV!C28,IF(B30=INV!B29,INV!C29,IF(B30=INV!B30,INV!C30,IF(B30=INV!B31,INV!C31,IF(B30=INV!B32,INV!C32,IF(B30=INV!B33,INV!C33,IF(B30=INV!B34,INV!C34,IF(B30=INV!B35,INV!C35,IF(B30=INV!B36,INV!C36,IF(B30=INV!B37,INV!C37,IF(B30=INV!B38,INV!C38,IF(B30=INV!B39,INV!C39,IF(B30=INV!B40,INV!C40,IF(B30=INV!B41,INV!C331,IF(B30=INV!B42,INV!C42,IF(B30=INV!B43,INV!C43,IF(B30=INV!B44,INV!C44,IF(B30=INV!B45,INV!C45,IF(B30=INV!B46,INV!C46,IF(B30=INV!B47,INV!C47,IF(B30=INV!B48,INV!C48,IF(B30=INV!B49,INV!C49,IF(B30=INV!B50,INV!C50,IF(B30=INV!B51,INV!C51,IF(B30=INV!B52,INV!C52,IF(B30=INV!B53,INV!C53,IF(B30=INV!B54,INV!C54,IF(B30=INV!B55,INV!C55,IF(B30=INV!B56,INV!C56,IF(B30=INV!B57,INV!C57,IF(B30=INV!B58,INV!C58,IF(B30=INV!B59,INV!C59,IF(B30=INV!B60,INV!C60)))))))))))))))))))))))))))))))))))))))))))))))))))))))))))) | D30: =IF(C30="","",IF(C30=INV!C2,INV!D2,IF(C30=INV!C3,INV!D3,IF(C30=INV!C4,INV!D4,IF(C30=INV!C5,INV!D5,IF(C30=INV!C6,INV!D6,IF(C30=INV!C7,INV!D7,IF(C30=INV!C8,INV!D8,IF(C30=INV!C9,INV!D9,IF(C30=INV!C10,INV!D10,IF(C30=INV!C11,INV!D11,IF(C30=INV!C12,INV!D12,IF(C30=INV!C13,INV!D13,IF(C30=INV!C14,INV!D14,IF(C30=INV!C15,INV!D15,IF(C30=INV!C16,INV!D16,IF(C30=INV!C17,INV!D17,IF(C30=INV!C18,INV!D18,IF(C30=INV!C19,INV!D19,IF(C30=INV!C20,INV!D20,IF(C30=INV!C21,INV!D21,IF(C30=INV!C22,INV!D22,IF(C30=INV!C23,INV!D23,IF(C30=INV!C24,INV!D24,IF(C30=INV!C25,INV!D25,IF(C30=INV!C26,INV!D26,IF(C30=INV!C27,INV!D27,IF(C30=INV!C28,INV!D28,IF(C30=INV!C29,INV!D29,IF(C30=INV!C30,INV!D30,IF(C30=INV!C31,INV!D31,IF(C30=INV!C32,INV!D32,IF(C30=INV!C33,INV!D33,IF(C30=INV!C34,INV!D34,IF(C30=INV!C35,INV!D35,IF(C30=INV!C36,INV!D36,IF(C30=INV!C37,INV!D37,IF(C30=INV!C38,INV!D38,IF(C30=INV!C39,INV!D39,IF(C30=INV!C40,INV!D40,IF(C30=INV!C41,INV!D331,IF(C30=INV!C42,INV!D42,IF(C30=INV!C43,INV!D43,IF(C30=INV!C44,INV!D44,IF(C30=INV!C45,INV!D45,IF(C30=INV!C46,INV!D46,IF(C30=INV!C47,INV!D47,IF(C30=INV!C48,INV!D48,IF(C30=INV!C49,INV!D49,IF(C30=INV!C50,INV!D50,IF(C30=INV!C51,INV!D51,IF(C30=INV!C52,INV!D52,IF(C30=INV!C53,INV!D53,IF(C30=INV!C54,INV!D54,IF(C30=INV!C55,INV!D55,IF(C30=INV!C56,INV!D56,IF(C30=INV!C57,INV!D57,IF(C30=INV!C58,INV!D58,IF(C30=INV!C59,INV!D59,IF(C30=INV!C60,INV!D60)))))))))))))))))))))))))))))))))))))))))))))))))))))))))))) | G30: =IF(B30="","",IF(B30=INV!B2,INV!F2,IF(B30=INV!B3,INV!F3,IF(B30=INV!B4,INV!F4,IF(B30=INV!B5,INV!F5,IF(B30=INV!B6,INV!F6,IF(B30=INV!B7,INV!F7,IF(B30=INV!B8,INV!F8,IF(B30=INV!B9,INV!F9,IF(B30=INV!B10,INV!F10,IF(B30=INV!B11,INV!F11,IF(B30=INV!B12,INV!F12,IF(B30=INV!B13,INV!F13,IF(B30=INV!B14,INV!F14,IF(B30=INV!B15,INV!F15,IF(B30=INV!B16,INV!F16,IF(B30=INV!B17,INV!F17,IF(B30=INV!B18,INV!F18,IF(B30=INV!B19,INV!F19,IF(B30=INV!B20,INV!F20,IF(B30=INV!B21,INV!F21,IF(B30=INV!B22,INV!F22,IF(B30=INV!B23,INV!F23,IF(B30=INV!B24,INV!F24,IF(B30=INV!B25,INV!F25,IF(B30=INV!B26,INV!F26,IF(B30=INV!B27,INV!F27,IF(B30=INV!B28,INV!F28,IF(B30=INV!B29,INV!F29,IF(B30=INV!B30,INV!F30,IF(B30=INV!B31,INV!F31,IF(B30=INV!B32,INV!F32,IF(B30=INV!B33,INV!F33,IF(B30=INV!B34,INV!F34,IF(B30=INV!B35,INV!F35,IF(B30=INV!B36,INV!F36,IF(B30=INV!B37,INV!F37,IF(B30=INV!B38,INV!F38,IF(B30=INV!B39,INV!F39,IF(B30=INV!B40,INV!F40,IF(B30=INV!B41,INV!F41,IF(B30=INV!B42,INV!F42,IF(B30=INV!B43,INV!F43,IF(B30=INV!B44,INV!F44,IF(B30=INV!B45,INV!F45,IF(B30=INV!B46,INV!F46,IF(B30=INV!B47,INV!F47,IF(B30=INV!B48,INV!F48,IF(B30=INV!B49,INV!F49,IF(B30=INV!B50,INV!F50,IF(B30=INV!B51,INV!F51,IF(B30=INV!B52,INV!F52,IF(B30=INV!B53,INV!F53,IF(B30=INV!B54,INV!F54,IF(B30=INV!B55,INV!F55,IF(B30=INV!B56,INV!F56,IF(B30=INV!B57,INV!F57,IF(B30=INV!B58,INV!F58,IF(B30=INV!B60,INV!F60))))))))))))))))))))))))))))))))))))))))))))))))))))))))))) | H30: =IF(F30="","",G30*F30)
C31: =IF(B31="","",IF(B31=INV!B2,INV!C2,IF(B31=INV!B3,INV!C3,IF(B31=INV!B4,INV!C4,IF(B31=INV!B5,INV!C5,IF(B31=INV!B6,INV!C6,IF(B31=INV!B7,INV!C7,IF(B31=INV!B8,INV!C8,IF(B31=INV!B9,INV!C9,IF(B31=INV!B10,INV!C10,IF(B31=INV!B11,INV!C11,IF(B31=INV!B12,INV!C12,IF(B31=INV!B13,INV!C13,IF(B31=INV!B14,INV!C14,IF(B31=INV!B15,INV!C15,IF(B31=INV!B16,INV!C16,IF(B31=INV!B17,INV!C17,IF(B31=INV!B18,INV!C18,IF(B31=INV!B19,INV!C19,IF(B31=INV!B20,INV!C20,IF(B31=INV!B21,INV!C21,IF(B31=INV!B22,INV!C22,IF(B31=INV!B23,INV!C23,IF(B31=INV!B24,INV!C24,IF(B31=INV!B25,INV!C25,IF(B31=INV!B26,INV!C26,IF(B31=INV!B27,INV!C27,IF(B31=INV!B28,INV!C28,IF(B31=INV!B29,INV!C29,IF(B31=INV!B30,INV!C30,IF(B31=INV!B31,INV!C31,IF(B31=INV!B32,INV!C32,IF(B31=INV!B33,INV!C33,IF(B31=INV!B34,INV!C34,IF(B31=INV!B35,INV!C35,IF(B31=INV!B36,INV!C36,IF(B31=INV!B37,INV!C37,IF(B31=INV!B38,INV!C38,IF(B31=INV!B39,INV!C39,IF(B31=INV!B40,INV!C40,IF(B31=INV!B41,INV!C41,IF(B31=INV!B42,INV!C332,IF(B31=INV!B43,INV!C43,IF(B31=INV!B44,INV!C44,IF(B31=INV!B45,INV!C45,IF(B31=INV!B46,INV!C46,IF(B31=INV!B47,INV!C47,IF(B31=INV!B48,INV!C48,IF(B31=INV!B49,INV!C49,IF(B31=INV!B50,INV!C50,IF(B31=INV!B51,INV!C51,IF(B31=INV!B52,INV!C52,IF(B31=INV!B53,INV!C53,IF(B31=INV!B54,INV!C54,IF(B31=INV!B55,INV!C55,IF(B31=INV!B56,INV!C56,IF(B31=INV!B57,INV!C57,IF(B31=INV!B58,INV!C58,IF(B31=INV!B59,INV!C59,IF(B31=INV!B60,INV!C60,IF(B31=INV!B61,INV!C61))))))))))))))))))))))))))))))))))))))))))))))))))))))))))))) | D31: =IF(C31="","",IF(C31=INV!C2,INV!D2,IF(C31=INV!C3,INV!D3,IF(C31=INV!C4,INV!D4,IF(C31=INV!C5,INV!D5,IF(C31=INV!C6,INV!D6,IF(C31=INV!C7,INV!D7,IF(C31=INV!C8,INV!D8,IF(C31=INV!C9,INV!D9,IF(C31=INV!C10,INV!D10,IF(C31=INV!C11,INV!D11,IF(C31=INV!C12,INV!D12,IF(C31=INV!C13,INV!D13,IF(C31=INV!C14,INV!D14,IF(C31=INV!C15,INV!D15,IF(C31=INV!C16,INV!D16,IF(C31=INV!C17,INV!D17,IF(C31=INV!C18,INV!D18,IF(C31=INV!C19,INV!D19,IF(C31=INV!C20,INV!D20,IF(C31=INV!C21,INV!D21,IF(C31=INV!C22,INV!D22,IF(C31=INV!C23,INV!D23,IF(C31=INV!C24,INV!D24,IF(C31=INV!C25,INV!D25,IF(C31=INV!C26,INV!D26,IF(C31=INV!C27,INV!D27,IF(C31=INV!C28,INV!D28,IF(C31=INV!C29,INV!D29,IF(C31=INV!C30,INV!D30,IF(C31=INV!C31,INV!D31,IF(C31=INV!C32,INV!D32,IF(C31=INV!C33,INV!D33,IF(C31=INV!C34,INV!D34,IF(C31=INV!C35,INV!D35,IF(C31=INV!C36,INV!D36,IF(C31=INV!C37,INV!D37,IF(C31=INV!C38,INV!D38,IF(C31=INV!C39,INV!D39,IF(C31=INV!C40,INV!D40,IF(C31=INV!C41,INV!D41,IF(C31=INV!C42,INV!D332,IF(C31=INV!C43,INV!D43,IF(C31=INV!C44,INV!D44,IF(C31=INV!C45,INV!D45,IF(C31=INV!C46,INV!D46,IF(C31=INV!C47,INV!D47,IF(C31=INV!C48,INV!D48,IF(C31=INV!C49,INV!D49,IF(C31=INV!C50,INV!D50,IF(C31=INV!C51,INV!D51,IF(C31=INV!C52,INV!D52,IF(C31=INV!C53,INV!D53,IF(C31=INV!C54,INV!D54,IF(C31=INV!C55,INV!D55,IF(C31=INV!C56,INV!D56,IF(C31=INV!C57,INV!D57,IF(C31=INV!C58,INV!D58,IF(C31=INV!C59,INV!D59,IF(C31=INV!C60,INV!D60,IF(C31=INV!C61,INV!D61))))))))))))))))))))))))))))))))))))))))))))))))))))))))))))) | G31: =IF(B31="","",IF(B31=INV!B2,INV!F2,IF(B31=INV!B3,INV!F3,IF(B31=INV!B4,INV!F4,IF(B31=INV!B5,INV!F5,IF(B31=INV!B6,INV!F6,IF(B31=INV!B7,INV!F7,IF(B31=INV!B8,INV!F8,IF(B31=INV!B9,INV!F9,IF(B31=INV!B10,INV!F10,IF(B31=INV!B11,INV!F11,IF(B31=INV!B12,INV!F12,IF(B31=INV!B13,INV!F13,IF(B31=INV!B14,INV!F14,IF(B31=INV!B15,INV!F15,IF(B31=INV!B16,INV!F16,IF(B31=INV!B17,INV!F17,IF(B31=INV!B18,INV!F18,IF(B31=INV!B19,INV!F19,IF(B31=INV!B20,INV!F20,IF(B31=INV!B21,INV!F21,IF(B31=INV!B22,INV!F22,IF(B31=INV!B23,INV!F23,IF(B31=INV!B24,INV!F24,IF(B31=INV!B25,INV!F25,IF(B31=INV!B26,INV!F26,IF(B31=INV!B27,INV!F27,IF(B31=INV!B28,INV!F28,IF(B31=INV!B29,INV!F29,IF(B31=INV!B30,INV!F30,IF(B31=INV!B31,INV!F31,IF(B31=INV!B32,INV!F32,IF(B31=INV!B33,INV!F33,IF(B31=INV!B34,INV!F34,IF(B31=INV!B35,INV!F35,IF(B31=INV!B36,INV!F36,IF(B31=INV!B37,INV!F37,IF(B31=INV!B38,INV!F38,IF(B31=INV!B39,INV!F39,IF(B31=INV!B40,INV!F40,IF(B31=INV!B41,INV!F41,IF(B31=INV!B42,INV!F42,IF(B31=INV!B43,INV!F43,IF(B31=INV!B44,INV!F44,IF(B31=INV!B45,INV!F45,IF(B31=INV!B46,INV!F46,IF(B31=INV!B47,INV!F47,IF(B31=INV!B48,INV!F48,IF(B31=INV!B49,INV!F49,IF(B31=INV!B50,INV!F50,IF(B31=INV!B51,INV!F51,IF(B31=INV!B52,INV!F52,IF(B31=INV!B53,INV!F53,IF(B31=INV!B54,INV!F54,IF(B31=INV!B55,INV!F55,IF(B31=INV!B56,INV!F56,IF(B31=INV!B57,INV!F57,IF(B31=INV!B58,INV!F58,IF(B31=INV!B59,INV!F59,IF(B31=INV!B60,INV!F60)))))))))))))))))))))))))))))))))))))))))))))))))))))))))))) | H31: =IF(F31="","",G31*F31)
D33: TOTAL A CANCELAR: | E33: CANT. | F33: SKU | G33: DCTO. PROM. | H33: COSTO
E34: =SUM(F21:F31) -> 0 | F34: =COUNT(F21:F31) -> 0 | G34: =IF(H17="NO","",IF(H17="SI",SUM(H21:H31)*10%)) | H34: =IF(H17="NO",SUM(H21:H31),SUM(H21:H31)-G34) -> 0

Sheet NOTA BS
A1: NOTA DE ENTREGA
B5: SUMINISTROS Y ACCESORIOS CARABOBO
B6: AV. ANDRÉS BELLO C/C LÓPEZ, LOCAL NRO, 87-66 SECTOR LA CANDELA
B7: RIF: J075102593
B8: TELÉFONO: 0212-8870026
B10: CLIENTE: | G10: FECHA: | H10: =NOW() -> 46280.588
B12: C.I. / RIF: | G12: N° DOC: | H12: =51437+H10+G34 -> 97717.588
B14: TELÉFONO: | G14: VENDEDOR: | H14: V-09036
B16: DIRECCION: | G16: TIPO DE PAGO: | H16: PAGO MÓVIL
G17: TASA B.C.V.: | H17: 842.21
B19: CÓDIGO | C19: CÓD. UNIX | D19: DESCRIPCIÓN | F19: CANTIDAD | G19: PRECIO Bs. | H19: TOTAL Bs.
C21: =IF(B21="","",IF(B21=INV!B2,INV!C2,IF(B21=INV!B3,INV!C3,IF(B21=INV!B4,INV!C4,IF(B21=INV!B5,INV!C5,IF(B21=INV!B6,INV!C6,IF(B21=INV!B7,INV!C7,IF(B21=INV!B8,INV!C8,IF(B21=INV!B9,INV!C9,IF(B21=INV!B10,INV!C10,IF(B21=INV!B11,INV!C11,IF(B21=INV!B12,INV!C12,IF(B21=INV!B13,INV!C13,IF(B21=INV!B14,INV!C14,IF(B21=INV!B15,INV!C15,IF(B21=INV!B16,INV!C16,IF(B21=INV!B17,INV!C17,IF(B21=INV!B18,INV!C18,IF(B21=INV!B19,INV!C19,IF(B21=INV!B20,INV!C20,IF(B21=INV!B21,INV!C21,IF(B21=INV!B22,INV!C22,IF(B21=INV!B23,INV!C23,IF(B21=INV!B24,INV!C24,IF(B21=INV!B25,INV!C25,IF(B21=INV!B26,INV!C26,IF(B21=INV!B27,INV!C27,IF(B21=INV!B28,INV!C28,IF(B21=INV!B29,INV!C29,IF(B21=INV!B30,INV!C30,IF(B21=INV!B31,INV!C31,IF(B21=INV!B32,INV!C322,IF(B21=INV!B33,INV!C33,IF(B21=INV!B34,INV!C34,IF(B21=INV!B35,INV!C35,IF(B21=INV!B36,INV!C36,IF(B21=INV!B37,INV!C37,IF(B21=INV!B38,INV!C38,IF(B21=INV!B39,INV!C39,IF(B21=INV!B40,INV!C40,IF(B21=INV!B41,INV!C41,IF(B21=INV!B42,INV!C42,IF(B21=INV!B43,INV!C43,IF(B21=INV!B44,INV!C44,IF(B21=INV!B45,INV!C45,IF(B21=INV!B46,INV!C46,IF(B21=INV!B47,INV!C47,IF(B21=INV!B48,INV!C48,IF(B21=INV!B49,INV!C49,IF(B21=INV!B50,INV!C50,IF(B21=INV!B51,INV!C51))))))))))))))))))))))))))))))))))))))))))))))))))) | D21: =IF(C21="","",IF(C21=INV!C2,INV!D2,IF(C21=INV!C3,INV!D3,IF(C21=INV!C4,INV!D4,IF(C21=INV!C5,INV!D5,IF(C21=INV!C6,INV!D6,IF(C21=INV!C7,INV!D7,IF(C21=INV!C8,INV!D8,IF(C21=INV!C9,INV!D9,IF(C21=INV!C10,INV!D10,IF(C21=INV!C11,INV!D11,IF(C21=INV!C12,INV!D12,IF(C21=INV!C13,INV!D13,IF(C21=INV!C14,INV!D14,IF(C21=INV!C15,INV!D15,IF(C21=INV!C16,INV!D16,IF(C21=INV!C17,INV!D17,IF(C21=INV!C18,INV!D18,IF(C21=INV!C19,INV!D19,IF(C21=INV!C20,INV!D20,IF(C21=INV!C21,INV!D21,IF(C21=INV!C22,INV!D22,IF(C21=INV!C23,INV!D23,IF(C21=INV!C24,INV!D24,IF(C21=INV!C25,INV!D25,IF(C21=INV!C26,INV!D26,IF(C21=INV!C27,INV!D27,IF(C21=INV!C28,INV!D28,IF(C21=INV!C29,INV!D29,IF(C21=INV!C30,INV!D30,IF(C21=INV!C31,INV!D31,IF(C21=INV!C32,INV!D322,IF(C21=INV!C33,INV!D33,IF(C21=INV!C34,INV!D34,IF(C21=INV!C35,INV!D35,IF(C21=INV!C36,INV!D36,IF(C21=INV!C37,INV!D37,IF(C21=INV!C38,INV!D38,IF(C21=INV!C39,INV!D39,IF(C21=INV!C40,INV!D40,IF(C21=INV!C41,INV!D41,IF(C21=INV!C42,INV!D42,IF(C21=INV!C43,INV!D43,IF(C21=INV!C44,INV!D44,IF(C21=INV!C45,INV!D45,IF(C21=INV!C46,INV!D46,IF(C21=INV!C47,INV!D47,IF(C21=INV!C48,INV!D48,IF(C21=INV!C49,INV!D49,IF(C21=INV!C50,INV!D50,IF(C21=INV!C51,INV!D51))))))))))))))))))))))))))))))))))))))))))))))))))) | G21: =IF(B21="","",IF(B21=INV!B2,INV!F2*H17,IF(B21=INV!B3,INV!F3*H17,IF(B21=INV!B4,INV!F4*H17,IF(B21=INV!B5,INV!F5*H17,IF(B21=INV!B6,INV!F6*H17,IF(B21=INV!B7,INV!F7*H17,IF(B21=INV!B8,INV!F8*H17,IF(B21=INV!B9,INV!F9*H17,IF(B21=INV!B10,INV!F10*H17,IF(B21=INV!B11,INV!F11*H17,IF(B21=INV!B12,INV!F12*H17,IF(B21=INV!B13,INV!F13*H17,IF(B21=INV!B14,INV!F14*H17,IF(B21=INV!B15,INV!F15*H17,IF(B21=INV!B16,INV!F16*H17,IF(B21=INV!B17,INV!F17*H17,IF(B21=INV!B18,INV!F18*H17,IF(B21=INV!B19,INV!F19*H17,IF(B21=INV!B20,INV!F20*H17,IF(B21=INV!B21,INV!F21*H17,IF(B21=INV!B22,INV!F22*H17,IF(B21=INV!B23,INV!F23*H17,IF(B21=INV!B24,INV!F24*H17,IF(B21=INV!B25,INV!F25*H17,IF(B21=INV!B26,INV!F26*H17,IF(B21=INV!B27,INV!F27*H17,IF(B21=INV!B28,INV!F28*H17,IF(B21=INV!B29,INV!F29*H17,IF(B21=INV!B30,INV!F30*H17,IF(B21=INV!B31,INV!F31*H17,IF(B21=INV!B32,INV!F32*H17,IF(B21=INV!B33,INV!F33*H17,IF(B21=INV!B34,INV!F34*H17,IF(B21=INV!B35,INV!F35*H17,IF(B21=INV!B36,INV!F36*H17,IF(B21=INV!B37,INV!F37*H17,IF(B21=INV!B38,INV!F38*H17,IF(B21=INV!B39,INV!F39*H17,IF(B21=INV!B40,INV!F40*H17,IF(B21=INV!B41,INV!F41*H17,IF(B21=INV!B42,INV!F42*H17,IF(B21=INV!B43,INV!F43*H17,IF(B21=INV!B44,INV!F44*H17,IF(B21=INV!B45,INV!F45*H17,IF(B21=INV!B46,INV!F46*H17,IF(B21=INV!B47,INV!F47*H17,IF(B21=INV!B48,INV!F48*H17,IF(B21=INV!B49,INV!F49*H17,IF(B21=INV!B50,INV!F50*H17,IF(B21=INV!B51,INV!F51*H17))))))))))))))))))))))))))))))))))))))))))))))))))) | H21: =IF(F21="","",G21*F21)
